[2025-03-14T18:53:37.703+0000] {local_task_job_runner.py:123} INFO - ::group::Pre task execution logs
[2025-03-14T18:53:37.738+0000] {taskinstance.py:2614} INFO - Dependencies all met for dep_context=non-requeueable deps ti=<TaskInstance: solar_energy_crops_pipeline.submit_spark_job manual__2025-03-09T19:18:27.013364+00:00 [queued]>
[2025-03-14T18:53:37.783+0000] {taskinstance.py:2614} INFO - Dependencies all met for dep_context=requeueable deps ti=<TaskInstance: solar_energy_crops_pipeline.submit_spark_job manual__2025-03-09T19:18:27.013364+00:00 [queued]>
[2025-03-14T18:53:37.784+0000] {taskinstance.py:2867} INFO - Starting attempt 3 of 4
[2025-03-14T18:53:37.806+0000] {taskinstance.py:2890} INFO - Executing <Task(SparkSubmitOperator): submit_spark_job> on 2025-03-09 19:18:27.013364+00:00
[2025-03-14T18:53:37.816+0000] {warnings.py:112} WARNING - /home/***/.local/lib/python3.12/site-packages/***/task/task_runner/standard_task_runner.py:70: DeprecationWarning: This process (pid=320) is multi-threaded, use of fork() may lead to deadlocks in the child.
  pid = os.fork()

[2025-03-14T18:53:37.817+0000] {standard_task_runner.py:104} INFO - Running: ['***', 'tasks', 'run', 'solar_energy_crops_pipeline', 'submit_spark_job', 'manual__2025-03-09T19:18:27.013364+00:00', '--job-id', '59', '--raw', '--subdir', 'DAGS_FOLDER/mainDag.py', '--cfg-path', '/tmp/tmp5idc_rbr']
[2025-03-14T18:53:37.821+0000] {standard_task_runner.py:72} INFO - Started process 322 to run task
[2025-03-14T18:53:37.821+0000] {standard_task_runner.py:105} INFO - Job 59: Subtask submit_spark_job
[2025-03-14T18:53:37.981+0000] {task_command.py:467} INFO - Running <TaskInstance: solar_energy_crops_pipeline.submit_spark_job manual__2025-03-09T19:18:27.013364+00:00 [running]> on host 87bb601a2791
[2025-03-14T18:53:38.125+0000] {taskinstance.py:3134} INFO - Exporting env vars: AIRFLOW_CTX_DAG_OWNER='***' AIRFLOW_CTX_DAG_ID='solar_energy_crops_pipeline' AIRFLOW_CTX_TASK_ID='submit_spark_job' AIRFLOW_CTX_EXECUTION_DATE='2025-03-09T19:18:27.013364+00:00' AIRFLOW_CTX_TRY_NUMBER='3' AIRFLOW_CTX_DAG_RUN_ID='manual__2025-03-09T19:18:27.013364+00:00'
[2025-03-14T18:53:38.127+0000] {taskinstance.py:732} INFO - ::endgroup::
[2025-03-14T18:53:38.217+0000] {base.py:84} INFO - Retrieving connection 'spark_default'
[2025-03-14T18:53:38.220+0000] {spark_submit.py:335} INFO - Spark-Submit cmd: spark-submit --master spark-master:7077 --conf spark.master=spark://spark-master:7077 --packages org.postgresql:postgresql:42.2.5 --name arrow-spark ./dags/transform.py
[2025-03-14T18:53:52.184+0000] {spark_submit.py:488} INFO - :: loading settings :: url = jar:file:/home/***/.local/lib/python3.12/site-packages/pyspark/jars/ivy-2.5.1.jar!/org/apache/ivy/core/settings/ivysettings.xml
[2025-03-14T18:53:52.789+0000] {spark_submit.py:488} INFO - Ivy Default Cache set to: /home/***/.ivy2/cache
[2025-03-14T18:53:52.871+0000] {spark_submit.py:488} INFO - The jars for the packages stored in: /home/***/.ivy2/jars
[2025-03-14T18:53:52.876+0000] {spark_submit.py:488} INFO - org.postgresql#postgresql added as a dependency
[2025-03-14T18:53:52.877+0000] {spark_submit.py:488} INFO - :: resolving dependencies :: org.apache.spark#spark-submit-parent-0262405a-72d3-4b6f-979a-0531b5ecfc3d;1.0
[2025-03-14T18:53:52.878+0000] {spark_submit.py:488} INFO - confs: [default]
[2025-03-14T18:53:53.688+0000] {spark_submit.py:488} INFO - found org.postgresql#postgresql;42.2.5 in central
[2025-03-14T18:53:53.786+0000] {spark_submit.py:488} INFO - :: resolution report :: resolve 904ms :: artifacts dl 5ms
[2025-03-14T18:53:53.787+0000] {spark_submit.py:488} INFO - :: modules in use:
[2025-03-14T18:53:53.788+0000] {spark_submit.py:488} INFO - org.postgresql#postgresql;42.2.5 from central in [default]
[2025-03-14T18:53:53.790+0000] {spark_submit.py:488} INFO - ---------------------------------------------------------------------
[2025-03-14T18:53:53.791+0000] {spark_submit.py:488} INFO - |                  |            modules            ||   artifacts   |
[2025-03-14T18:53:53.872+0000] {spark_submit.py:488} INFO - |       conf       | number| search|dwnlded|evicted|| number|dwnlded|
[2025-03-14T18:53:53.873+0000] {spark_submit.py:488} INFO - ---------------------------------------------------------------------
[2025-03-14T18:53:53.875+0000] {spark_submit.py:488} INFO - |      default     |   1   |   0   |   0   |   0   ||   1   |   0   |
[2025-03-14T18:53:53.877+0000] {spark_submit.py:488} INFO - ---------------------------------------------------------------------
[2025-03-14T18:53:53.878+0000] {spark_submit.py:488} INFO - :: retrieving :: org.apache.spark#spark-submit-parent-0262405a-72d3-4b6f-979a-0531b5ecfc3d
[2025-03-14T18:53:53.879+0000] {spark_submit.py:488} INFO - confs: [default]
[2025-03-14T18:53:53.987+0000] {spark_submit.py:488} INFO - 1 artifacts copied, 0 already retrieved (806kB/112ms)
[2025-03-14T18:53:55.687+0000] {spark_submit.py:488} INFO - 25/03/14 18:53:55 WARN NativeCodeLoader: Unable to load native-hadoop library for your platform... using builtin-java classes where applicable
[2025-03-14T18:54:41.010+0000] {job.py:239} ERROR - Job heartbeat failed with error
Traceback (most recent call last):
  File "/home/airflow/.local/lib/python3.12/site-packages/sqlalchemy/engine/base.py", line 3371, in _wrap_pool_connect
    return fn()
           ^^^^
  File "/home/airflow/.local/lib/python3.12/site-packages/sqlalchemy/pool/base.py", line 327, in connect
    return _ConnectionFairy._checkout(self)
           ^^^^^^^^^^^^^^^^^^^^^^^^^^^^^^^^
  File "/home/airflow/.local/lib/python3.12/site-packages/sqlalchemy/pool/base.py", line 894, in _checkout
    fairy = _ConnectionRecord.checkout(pool)
            ^^^^^^^^^^^^^^^^^^^^^^^^^^^^^^^^
  File "/home/airflow/.local/lib/python3.12/site-packages/sqlalchemy/pool/base.py", line 493, in checkout
    rec = pool._do_get()
          ^^^^^^^^^^^^^^
  File "/home/airflow/.local/lib/python3.12/site-packages/sqlalchemy/pool/impl.py", line 256, in _do_get
    return self._create_connection()
           ^^^^^^^^^^^^^^^^^^^^^^^^^
  File "/home/airflow/.local/lib/python3.12/site-packages/sqlalchemy/pool/base.py", line 273, in _create_connection
    return _ConnectionRecord(self)
           ^^^^^^^^^^^^^^^^^^^^^^^
  File "/home/airflow/.local/lib/python3.12/site-packages/sqlalchemy/pool/base.py", line 388, in __init__
    self.__connect()
  File "/home/airflow/.local/lib/python3.12/site-packages/sqlalchemy/pool/base.py", line 690, in __connect
    with util.safe_reraise():
         ^^^^^^^^^^^^^^^^^^^
  File "/home/airflow/.local/lib/python3.12/site-packages/sqlalchemy/util/langhelpers.py", line 70, in __exit__
    compat.raise_(
  File "/home/airflow/.local/lib/python3.12/site-packages/sqlalchemy/util/compat.py", line 211, in raise_
    raise exception
  File "/home/airflow/.local/lib/python3.12/site-packages/sqlalchemy/pool/base.py", line 686, in __connect
    self.dbapi_connection = connection = pool._invoke_creator(self)
                                         ^^^^^^^^^^^^^^^^^^^^^^^^^^
  File "/home/airflow/.local/lib/python3.12/site-packages/sqlalchemy/engine/create.py", line 574, in connect
    return dialect.connect(*cargs, **cparams)
           ^^^^^^^^^^^^^^^^^^^^^^^^^^^^^^^^^^
  File "/home/airflow/.local/lib/python3.12/site-packages/sqlalchemy/engine/default.py", line 598, in connect
    return self.dbapi.connect(*cargs, **cparams)
           ^^^^^^^^^^^^^^^^^^^^^^^^^^^^^^^^^^^^^
  File "/home/airflow/.local/lib/python3.12/site-packages/psycopg2/__init__.py", line 122, in connect
    conn = _connect(dsn, connection_factory=connection_factory, **kwasync)
           ^^^^^^^^^^^^^^^^^^^^^^^^^^^^^^^^^^^^^^^^^^^^^^^^^^^^^^^^^^^^^^^
psycopg2.OperationalError: could not translate host name "postgres" to address: Temporary failure in name resolution


The above exception was the direct cause of the following exception:

Traceback (most recent call last):
  File "/home/airflow/.local/lib/python3.12/site-packages/airflow/jobs/job.py", line 207, in heartbeat
    self._merge_from(Job._fetch_from_db(self, session))
                     ^^^^^^^^^^^^^^^^^^^^^^^^^^^^^^^^^
  File "/home/airflow/.local/lib/python3.12/site-packages/airflow/api_internal/internal_api_call.py", line 166, in wrapper
    return func(*args, **kwargs)
           ^^^^^^^^^^^^^^^^^^^^^
  File "/home/airflow/.local/lib/python3.12/site-packages/airflow/utils/session.py", line 94, in wrapper
    return func(*args, **kwargs)
           ^^^^^^^^^^^^^^^^^^^^^
  File "/home/airflow/.local/lib/python3.12/site-packages/airflow/utils/retries.py", line 93, in wrapped_function
    for attempt in run_with_db_retries(max_retries=retries, logger=logger, **retry_kwargs):
                   ^^^^^^^^^^^^^^^^^^^^^^^^^^^^^^^^^^^^^^^^^^^^^^^^^^^^^^^^^^^^^^^^^^^^^^^
  File "/home/airflow/.local/lib/python3.12/site-packages/tenacity/__init__.py", line 443, in __iter__
    do = self.iter(retry_state=retry_state)
         ^^^^^^^^^^^^^^^^^^^^^^^^^^^^^^^^^^
  File "/home/airflow/.local/lib/python3.12/site-packages/tenacity/__init__.py", line 376, in iter
    result = action(retry_state)
             ^^^^^^^^^^^^^^^^^^^
  File "/home/airflow/.local/lib/python3.12/site-packages/tenacity/__init__.py", line 418, in exc_check
    raise retry_exc.reraise()
          ^^^^^^^^^^^^^^^^^^^
  File "/home/airflow/.local/lib/python3.12/site-packages/tenacity/__init__.py", line 185, in reraise
    raise self.last_attempt.result()
          ^^^^^^^^^^^^^^^^^^^^^^^^^^
  File "/usr/local/lib/python3.12/concurrent/futures/_base.py", line 449, in result
    return self.__get_result()
           ^^^^^^^^^^^^^^^^^^^
  File "/usr/local/lib/python3.12/concurrent/futures/_base.py", line 401, in __get_result
    raise self._exception
  File "/home/airflow/.local/lib/python3.12/site-packages/airflow/utils/retries.py", line 102, in wrapped_function
    return func(*args, **kwargs)
           ^^^^^^^^^^^^^^^^^^^^^
  File "/home/airflow/.local/lib/python3.12/site-packages/airflow/jobs/job.py", line 335, in _fetch_from_db
    session.merge(job)
  File "/home/airflow/.local/lib/python3.12/site-packages/sqlalchemy/orm/session.py", line 3056, in merge
    return self._merge(
           ^^^^^^^^^^^^
  File "/home/airflow/.local/lib/python3.12/site-packages/sqlalchemy/orm/session.py", line 3136, in _merge
    merged = self.get(
             ^^^^^^^^^
  File "/home/airflow/.local/lib/python3.12/site-packages/sqlalchemy/orm/session.py", line 2853, in get
    return self._get_impl(
           ^^^^^^^^^^^^^^^
  File "/home/airflow/.local/lib/python3.12/site-packages/sqlalchemy/orm/session.py", line 2975, in _get_impl
    return db_load_fn(
           ^^^^^^^^^^^
  File "/home/airflow/.local/lib/python3.12/site-packages/sqlalchemy/orm/loading.py", line 530, in load_on_pk_identity
    session.execute(
  File "/home/airflow/.local/lib/python3.12/site-packages/sqlalchemy/orm/session.py", line 1716, in execute
    conn = self._connection_for_bind(bind)
           ^^^^^^^^^^^^^^^^^^^^^^^^^^^^^^^
  File "/home/airflow/.local/lib/python3.12/site-packages/sqlalchemy/orm/session.py", line 1555, in _connection_for_bind
    return self._transaction._connection_for_bind(
           ^^^^^^^^^^^^^^^^^^^^^^^^^^^^^^^^^^^^^^^
  File "/home/airflow/.local/lib/python3.12/site-packages/sqlalchemy/orm/session.py", line 750, in _connection_for_bind
    conn = bind.connect()
           ^^^^^^^^^^^^^^
  File "/home/airflow/.local/lib/python3.12/site-packages/sqlalchemy/future/engine.py", line 412, in connect
    return super(Engine, self).connect()
           ^^^^^^^^^^^^^^^^^^^^^^^^^^^^^
  File "/home/airflow/.local/lib/python3.12/site-packages/sqlalchemy/engine/base.py", line 3325, in connect
    return self._connection_cls(self, close_with_result=close_with_result)
           ^^^^^^^^^^^^^^^^^^^^^^^^^^^^^^^^^^^^^^^^^^^^^^^^^^^^^^^^^^^^^^^
  File "/home/airflow/.local/lib/python3.12/site-packages/sqlalchemy/engine/base.py", line 96, in __init__
    else engine.raw_connection()
         ^^^^^^^^^^^^^^^^^^^^^^^
  File "/home/airflow/.local/lib/python3.12/site-packages/sqlalchemy/engine/base.py", line 3404, in raw_connection
    return self._wrap_pool_connect(self.pool.connect, _connection)
           ^^^^^^^^^^^^^^^^^^^^^^^^^^^^^^^^^^^^^^^^^^^^^^^^^^^^^^^
  File "/home/airflow/.local/lib/python3.12/site-packages/sqlalchemy/engine/base.py", line 3374, in _wrap_pool_connect
    Connection._handle_dbapi_exception_noconnection(
  File "/home/airflow/.local/lib/python3.12/site-packages/sqlalchemy/engine/base.py", line 2208, in _handle_dbapi_exception_noconnection
    util.raise_(
  File "/home/airflow/.local/lib/python3.12/site-packages/sqlalchemy/util/compat.py", line 211, in raise_
    raise exception
  File "/home/airflow/.local/lib/python3.12/site-packages/sqlalchemy/engine/base.py", line 3371, in _wrap_pool_connect
    return fn()
           ^^^^
  File "/home/airflow/.local/lib/python3.12/site-packages/sqlalchemy/pool/base.py", line 327, in connect
    return _ConnectionFairy._checkout(self)
           ^^^^^^^^^^^^^^^^^^^^^^^^^^^^^^^^
  File "/home/airflow/.local/lib/python3.12/site-packages/sqlalchemy/pool/base.py", line 894, in _checkout
    fairy = _ConnectionRecord.checkout(pool)
            ^^^^^^^^^^^^^^^^^^^^^^^^^^^^^^^^
  File "/home/airflow/.local/lib/python3.12/site-packages/sqlalchemy/pool/base.py", line 493, in checkout
    rec = pool._do_get()
          ^^^^^^^^^^^^^^
  File "/home/airflow/.local/lib/python3.12/site-packages/sqlalchemy/pool/impl.py", line 256, in _do_get
    return self._create_connection()
           ^^^^^^^^^^^^^^^^^^^^^^^^^
  File "/home/airflow/.local/lib/python3.12/site-packages/sqlalchemy/pool/base.py", line 273, in _create_connection
    return _ConnectionRecord(self)
           ^^^^^^^^^^^^^^^^^^^^^^^
  File "/home/airflow/.local/lib/python3.12/site-packages/sqlalchemy/pool/base.py", line 388, in __init__
    self.__connect()
  File "/home/airflow/.local/lib/python3.12/site-packages/sqlalchemy/pool/base.py", line 690, in __connect
    with util.safe_reraise():
         ^^^^^^^^^^^^^^^^^^^
  File "/home/airflow/.local/lib/python3.12/site-packages/sqlalchemy/util/langhelpers.py", line 70, in __exit__
    compat.raise_(
  File "/home/airflow/.local/lib/python3.12/site-packages/sqlalchemy/util/compat.py", line 211, in raise_
    raise exception
  File "/home/airflow/.local/lib/python3.12/site-packages/sqlalchemy/pool/base.py", line 686, in __connect
    self.dbapi_connection = connection = pool._invoke_creator(self)
                                         ^^^^^^^^^^^^^^^^^^^^^^^^^^
  File "/home/airflow/.local/lib/python3.12/site-packages/sqlalchemy/engine/create.py", line 574, in connect
    return dialect.connect(*cargs, **cparams)
           ^^^^^^^^^^^^^^^^^^^^^^^^^^^^^^^^^^
  File "/home/airflow/.local/lib/python3.12/site-packages/sqlalchemy/engine/default.py", line 598, in connect
    return self.dbapi.connect(*cargs, **cparams)
           ^^^^^^^^^^^^^^^^^^^^^^^^^^^^^^^^^^^^^
  File "/home/airflow/.local/lib/python3.12/site-packages/psycopg2/__init__.py", line 122, in connect
    conn = _connect(dsn, connection_factory=connection_factory, **kwasync)
           ^^^^^^^^^^^^^^^^^^^^^^^^^^^^^^^^^^^^^^^^^^^^^^^^^^^^^^^^^^^^^^^
sqlalchemy.exc.OperationalError: (psycopg2.OperationalError) could not translate host name "postgres" to address: Temporary failure in name resolution

(Background on this error at: https://sqlalche.me/e/14/e3q8)
[2025-03-14T18:54:43.772+0000] {job.py:254} ERROR - Job heartbeat failed with error. Scheduler is in unhealthy state
[2025-03-14T18:55:23.216+0000] {spark_submit.py:488} INFO - 25/03/14 18:55:23 INFO SparkContext: Running Spark version 3.5.5
[2025-03-14T18:55:23.569+0000] {spark_submit.py:488} INFO - 25/03/14 18:55:23 INFO SparkContext: OS info Linux, 5.15.167.4-microsoft-standard-WSL2, amd64
[2025-03-14T18:55:23.713+0000] {job.py:254} ERROR - Job heartbeat failed with error. Scheduler is in unhealthy state
[2025-03-14T18:55:23.830+0000] {spark_submit.py:488} INFO - 25/03/14 18:55:23 INFO SparkContext: Java version 17.0.14
[2025-03-14T18:55:34.473+0000] {spark_submit.py:488} INFO - 25/03/14 18:55:34 INFO ResourceUtils: ==============================================================
[2025-03-14T18:55:34.530+0000] {spark_submit.py:488} INFO - 25/03/14 18:55:34 INFO ResourceUtils: No custom resources configured for spark.driver.
[2025-03-14T18:55:34.547+0000] {spark_submit.py:488} INFO - 25/03/14 18:55:34 INFO ResourceUtils: ==============================================================
[2025-03-14T18:55:34.591+0000] {spark_submit.py:488} INFO - 25/03/14 18:55:34 INFO SparkContext: Submitted application: WeatherDataTransformation
[2025-03-14T18:56:22.816+0000] {job.py:254} ERROR - Job heartbeat failed with error. Scheduler is in unhealthy state
[2025-03-14T18:57:34.960+0000] {spark_submit.py:488} INFO - 25/03/14 18:57:34 INFO ResourceProfile: Default ResourceProfile created, executor resources: Map(cores -> name: cores, amount: 1, script: , vendor: , memory -> name: memory, amount: 1024, script: , vendor: , offHeap -> name: offHeap, amount: 0, script: , vendor: ), task resources: Map(cpus -> name: cpus, amount: 1.0)
[2025-03-14T18:57:35.015+0000] {spark_submit.py:488} INFO - 25/03/14 18:57:35 INFO ResourceProfile: Limiting resource is cpu
[2025-03-14T18:57:35.071+0000] {spark_submit.py:488} INFO - 25/03/14 18:57:35 INFO ResourceProfileManager: Added ResourceProfile id: 0
[2025-03-14T18:57:35.606+0000] {spark_submit.py:488} INFO - 25/03/14 18:57:35 INFO SecurityManager: Changing view acls to: ***
[2025-03-14T18:57:35.674+0000] {spark_submit.py:488} INFO - 25/03/14 18:57:35 INFO SecurityManager: Changing modify acls to: ***
[2025-03-14T18:57:35.678+0000] {spark_submit.py:488} INFO - 25/03/14 18:57:35 INFO SecurityManager: Changing view acls groups to:
[2025-03-14T18:57:35.681+0000] {spark_submit.py:488} INFO - 25/03/14 18:57:35 INFO SecurityManager: Changing modify acls groups to:
[2025-03-14T18:57:35.686+0000] {spark_submit.py:488} INFO - 25/03/14 18:57:35 INFO SecurityManager: SecurityManager: authentication disabled; ui acls disabled; users with view permissions: ***; groups with view permissions: EMPTY; users with modify permissions: ***; groups with modify permissions: EMPTY
[2025-03-14T18:57:39.480+0000] {spark_submit.py:488} INFO - 25/03/14 18:57:39 INFO Utils: Successfully started service 'sparkDriver' on port 40263.
[2025-03-14T18:57:39.923+0000] {spark_submit.py:488} INFO - 25/03/14 18:57:39 INFO SparkEnv: Registering MapOutputTracker
[2025-03-14T18:57:40.431+0000] {spark_submit.py:488} INFO - 25/03/14 18:57:40 INFO SparkEnv: Registering BlockManagerMaster
[2025-03-14T18:57:41.074+0000] {spark_submit.py:488} INFO - 25/03/14 18:57:41 INFO BlockManagerMasterEndpoint: Using org.apache.spark.storage.DefaultTopologyMapper for getting topology information
[2025-03-14T18:57:41.137+0000] {spark_submit.py:488} INFO - 25/03/14 18:57:41 INFO BlockManagerMasterEndpoint: BlockManagerMasterEndpoint up
[2025-03-14T18:57:41.486+0000] {spark_submit.py:488} INFO - 25/03/14 18:57:41 INFO SparkEnv: Registering BlockManagerMasterHeartbeat
[2025-03-14T18:57:46.478+0000] {spark_submit.py:488} INFO - 25/03/14 18:57:46 INFO DiskBlockManager: Created local directory at /tmp/blockmgr-9e42f495-12d4-4f1d-8451-a2e53ae27b36
[2025-03-14T18:57:50.992+0000] {spark_submit.py:488} INFO - 25/03/14 18:57:50 INFO MemoryStore: MemoryStore started with capacity 413.9 MiB
[2025-03-14T18:58:07.735+0000] {job.py:254} ERROR - Job heartbeat failed with error. Scheduler is in unhealthy state
[2025-03-14T18:58:16.315+0000] {spark_submit.py:488} INFO - 25/03/14 18:58:16 INFO SparkEnv: Registering OutputCommitCoordinator
[2025-03-14T18:58:18.707+0000] {spark_submit.py:488} INFO - 25/03/14 18:58:18 INFO JettyUtils: Start Jetty 0.0.0.0:4040 for SparkUI
[2025-03-14T18:58:48.019+0000] {job.py:254} ERROR - Job heartbeat failed with error. Scheduler is in unhealthy state
[2025-03-14T18:59:54.507+0000] {job.py:254} ERROR - Job heartbeat failed with error. Scheduler is in unhealthy state
[2025-03-14T18:59:55.979+0000] {local_task_job_runner.py:228} ERROR - Heartbeat time limit exceeded!
[2025-03-14T18:59:55.983+0000] {local_task_job_runner.py:245} INFO - ::endgroup::
[2025-03-14T18:59:56.076+0000] {process_utils.py:132} INFO - Sending 15 to group 322. PIDs of all processes in the group: [327, 431, 322]
[2025-03-14T18:59:56.078+0000] {process_utils.py:87} INFO - Sending the signal 15 to group 322
[2025-03-14T18:59:56.087+0000] {taskinstance.py:3094} ERROR - Received SIGTERM. Terminating subprocesses.
[2025-03-14T18:59:56.093+0000] {process_utils.py:80} INFO - Process psutil.Process(pid=431, status='terminated', started='18:53:57') (431) terminated with exit code None
[2025-03-14T18:59:57.076+0000] {taskinstance.py:3095} ERROR - Stacktrace: 
  File "/home/***/.local/bin/***", line 8, in <module>
    sys.exit(main())
  File "/home/***/.local/lib/python3.12/site-packages/***/__main__.py", line 62, in main
    args.func(args)
  File "/home/***/.local/lib/python3.12/site-packages/***/cli/cli_config.py", line 49, in command
    return func(*args, **kwargs)
  File "/home/***/.local/lib/python3.12/site-packages/***/utils/cli.py", line 116, in wrapper
    return f(*args, **kwargs)
  File "/home/***/.local/lib/python3.12/site-packages/***/providers/celery/cli/celery_command.py", line 64, in wrapper
    providers_configuration_loaded(func)(*args, **kwargs)
  File "/home/***/.local/lib/python3.12/site-packages/***/utils/providers_configuration_loader.py", line 55, in wrapped_function
    return func(*args, **kwargs)
  File "/home/***/.local/lib/python3.12/site-packages/***/providers/celery/cli/celery_command.py", line 237, in worker
    _run_command_with_daemon_option(
  File "/home/***/.local/lib/python3.12/site-packages/***/providers/celery/cli/celery_command.py", line 50, in _run_command_with_daemon_option
    run_command_with_daemon_option(*args, **kwargs)
  File "/home/***/.local/lib/python3.12/site-packages/***/cli/commands/daemon_utils.py", line 86, in run_command_with_daemon_option
    callback()
  File "/home/***/.local/lib/python3.12/site-packages/***/providers/celery/cli/celery_command.py", line 230, in run_celery_worker
    celery_app.worker_main(options)
  File "/home/***/.local/lib/python3.12/site-packages/celery/app/base.py", line 391, in worker_main
    self.start(argv=argv)
  File "/home/***/.local/lib/python3.12/site-packages/celery/app/base.py", line 371, in start
    celery.main(args=argv, standalone_mode=False)
  File "/home/***/.local/lib/python3.12/site-packages/click/core.py", line 1082, in main
    rv = self.invoke(ctx)
  File "/home/***/.local/lib/python3.12/site-packages/click/core.py", line 1697, in invoke
    return _process_result(sub_ctx.command.invoke(sub_ctx))
  File "/home/***/.local/lib/python3.12/site-packages/click/core.py", line 1443, in invoke
    return ctx.invoke(self.callback, **ctx.params)
  File "/home/***/.local/lib/python3.12/site-packages/click/core.py", line 788, in invoke
    return __callback(*args, **kwargs)
  File "/home/***/.local/lib/python3.12/site-packages/click/decorators.py", line 33, in new_func
    return f(get_current_context(), *args, **kwargs)
  File "/home/***/.local/lib/python3.12/site-packages/celery/bin/base.py", line 135, in caller
    return f(ctx, *args, **kwargs)
  File "/home/***/.local/lib/python3.12/site-packages/celery/bin/worker.py", line 356, in worker
    worker.start()
  File "/home/***/.local/lib/python3.12/site-packages/celery/worker/worker.py", line 202, in start
    self.blueprint.start(self)
  File "/home/***/.local/lib/python3.12/site-packages/celery/bootsteps.py", line 116, in start
    step.start(parent)
  File "/home/***/.local/lib/python3.12/site-packages/celery/bootsteps.py", line 365, in start
    return self.obj.start()
  File "/home/***/.local/lib/python3.12/site-packages/celery/concurrency/base.py", line 130, in start
    self.on_start()
  File "/home/***/.local/lib/python3.12/site-packages/celery/concurrency/prefork.py", line 109, in on_start
    P = self._pool = Pool(processes=self.limit,
  File "/home/***/.local/lib/python3.12/site-packages/celery/concurrency/asynpool.py", line 464, in __init__
    super().__init__(processes, *args, **kwargs)
  File "/home/***/.local/lib/python3.12/site-packages/billiard/pool.py", line 1046, in __init__
    self._create_worker_process(i)
  File "/home/***/.local/lib/python3.12/site-packages/celery/concurrency/asynpool.py", line 482, in _create_worker_process
    return super()._create_worker_process(i)
  File "/home/***/.local/lib/python3.12/site-packages/billiard/pool.py", line 1158, in _create_worker_process
    w.start()
  File "/home/***/.local/lib/python3.12/site-packages/billiard/process.py", line 120, in start
    self._popen = self._Popen(self)
  File "/home/***/.local/lib/python3.12/site-packages/billiard/context.py", line 331, in _Popen
    return Popen(process_obj)
  File "/home/***/.local/lib/python3.12/site-packages/billiard/popen_fork.py", line 22, in __init__
    self._launch(process_obj)
  File "/home/***/.local/lib/python3.12/site-packages/billiard/popen_fork.py", line 77, in _launch
    code = process_obj._bootstrap()
  File "/home/***/.local/lib/python3.12/site-packages/billiard/process.py", line 323, in _bootstrap
    self.run()
  File "/home/***/.local/lib/python3.12/site-packages/billiard/process.py", line 110, in run
    self._target(*self._args, **self._kwargs)
  File "/home/***/.local/lib/python3.12/site-packages/billiard/pool.py", line 292, in __call__
    sys.exit(self.workloop(pid=pid))
  File "/home/***/.local/lib/python3.12/site-packages/billiard/pool.py", line 362, in workloop
    result = (True, prepare_result(fun(*args, **kwargs)))
  File "/home/***/.local/lib/python3.12/site-packages/celery/app/trace.py", line 651, in fast_trace_task
    R, I, T, Rstr = tasks[task].__trace__(
  File "/home/***/.local/lib/python3.12/site-packages/celery/app/trace.py", line 453, in trace_task
    R = retval = fun(*args, **kwargs)
  File "/home/***/.local/lib/python3.12/site-packages/celery/app/trace.py", line 736, in __protected_call__
    return self.run(*args, **kwargs)
  File "/home/***/.local/lib/python3.12/site-packages/***/providers/celery/executors/celery_executor_utils.py", line 139, in execute_command
    _execute_in_fork(command_to_exec, celery_task_id)
  File "/home/***/.local/lib/python3.12/site-packages/***/providers/celery/executors/celery_executor_utils.py", line 171, in _execute_in_fork
    args.func(args)
  File "/home/***/.local/lib/python3.12/site-packages/***/cli/cli_config.py", line 49, in command
    return func(*args, **kwargs)
  File "/home/***/.local/lib/python3.12/site-packages/***/utils/cli.py", line 116, in wrapper
    return f(*args, **kwargs)
  File "/home/***/.local/lib/python3.12/site-packages/***/cli/commands/task_command.py", line 483, in task_run
    task_return_code = _run_task_by_selected_method(args, _dag, ti)
  File "/home/***/.local/lib/python3.12/site-packages/***/cli/commands/task_command.py", line 254, in _run_task_by_selected_method
    return _run_task_by_local_task_job(args, ti)
  File "/home/***/.local/lib/python3.12/site-packages/***/cli/commands/task_command.py", line 322, in _run_task_by_local_task_job
    ret = run_job(job=job_runner.job, execute_callable=job_runner._execute)
  File "/home/***/.local/lib/python3.12/site-packages/***/utils/session.py", line 97, in wrapper
    return func(*args, session=session, **kwargs)
  File "/home/***/.local/lib/python3.12/site-packages/***/jobs/job.py", line 421, in run_job
    return execute_job(job, execute_callable=execute_callable)
  File "/home/***/.local/lib/python3.12/site-packages/***/jobs/job.py", line 450, in execute_job
    ret = execute_callable()
  File "/home/***/.local/lib/python3.12/site-packages/***/jobs/local_task_job_runner.py", line 171, in _execute
    self.task_runner.start()
  File "/home/***/.local/lib/python3.12/site-packages/***/task/task_runner/standard_task_runner.py", line 55, in start
    self.process = self._start_by_fork()
  File "/home/***/.local/lib/python3.12/site-packages/***/task/task_runner/standard_task_runner.py", line 117, in _start_by_fork
    ret = args.func(args, dag=self.dag)
  File "/home/***/.local/lib/python3.12/site-packages/***/cli/cli_config.py", line 49, in command
    return func(*args, **kwargs)
  File "/home/***/.local/lib/python3.12/site-packages/***/utils/cli.py", line 116, in wrapper
    return f(*args, **kwargs)
  File "/home/***/.local/lib/python3.12/site-packages/***/cli/commands/task_command.py", line 483, in task_run
    task_return_code = _run_task_by_selected_method(args, _dag, ti)
  File "/home/***/.local/lib/python3.12/site-packages/***/cli/commands/task_command.py", line 256, in _run_task_by_selected_method
    return _run_raw_task(args, ti)
  File "/home/***/.local/lib/python3.12/site-packages/***/cli/commands/task_command.py", line 341, in _run_raw_task
    return ti._run_raw_task(
  File "/home/***/.local/lib/python3.12/site-packages/***/utils/session.py", line 97, in wrapper
    return func(*args, session=session, **kwargs)
  File "/home/***/.local/lib/python3.12/site-packages/***/models/taskinstance.py", line 3006, in _run_raw_task
    return _run_raw_task(
  File "/home/***/.local/lib/python3.12/site-packages/***/models/taskinstance.py", line 274, in _run_raw_task
    TaskInstance._execute_task_with_callbacks(
  File "/home/***/.local/lib/python3.12/site-packages/***/models/taskinstance.py", line 3161, in _execute_task_with_callbacks
    result = self._execute_task(context, task_orig)
  File "/home/***/.local/lib/python3.12/site-packages/***/models/taskinstance.py", line 3185, in _execute_task
    return _execute_task(self, context, task_orig)
  File "/home/***/.local/lib/python3.12/site-packages/***/models/taskinstance.py", line 768, in _execute_task
    result = _execute_callable(context=context, **execute_callable_kwargs)
  File "/home/***/.local/lib/python3.12/site-packages/***/models/taskinstance.py", line 734, in _execute_callable
    return ExecutionCallableRunner(
  File "/home/***/.local/lib/python3.12/site-packages/***/utils/operator_helpers.py", line 252, in run
    return self.func(*args, **kwargs)
  File "/home/***/.local/lib/python3.12/site-packages/***/models/baseoperator.py", line 424, in wrapper
    return func(self, *args, **kwargs)
  File "/home/***/.local/lib/python3.12/site-packages/***/providers/apache/spark/operators/spark_submit.py", line 157, in execute
    self._hook.submit(self._application)
  File "/home/***/.local/lib/python3.12/site-packages/***/providers/apache/spark/hooks/spark_submit.py", line 407, in submit
    self._process_spark_submit_log(iter(self._submit_sp.stdout))  # type: ignore
  File "/home/***/.local/lib/python3.12/site-packages/***/providers/apache/spark/hooks/spark_submit.py", line 456, in _process_spark_submit_log
    for line in itr:
  File "/home/***/.local/lib/python3.12/site-packages/***/models/taskinstance.py", line 3095, in signal_handler
    self.log.error("Stacktrace: \n%s", "".join(traceback.format_stack()))

[2025-03-14T18:59:57.175+0000] {spark_submit.py:623} INFO - Sending kill signal to spark-submit
[2025-03-14T19:00:03.348+0000] {taskinstance.py:341} INFO - ::group::Post task execution logs
[2025-03-14T19:00:03.364+0000] {standard_task_runner.py:124} ERROR - Failed to execute job 59 for task submit_spark_job ((psycopg2.OperationalError) could not translate host name "postgres" to address: Temporary failure in name resolution

(Background on this error at: https://sqlalche.me/e/14/e3q8); 322)
Traceback (most recent call last):
  File "/home/airflow/.local/lib/python3.12/site-packages/airflow/models/taskinstance.py", line 274, in _run_raw_task
    TaskInstance._execute_task_with_callbacks(
  File "/home/airflow/.local/lib/python3.12/site-packages/airflow/models/taskinstance.py", line 3161, in _execute_task_with_callbacks
    result = self._execute_task(context, task_orig)
             ^^^^^^^^^^^^^^^^^^^^^^^^^^^^^^^^^^^^^^
  File "/home/airflow/.local/lib/python3.12/site-packages/airflow/models/taskinstance.py", line 3185, in _execute_task
    return _execute_task(self, context, task_orig)
           ^^^^^^^^^^^^^^^^^^^^^^^^^^^^^^^^^^^^^^^
  File "/home/airflow/.local/lib/python3.12/site-packages/airflow/models/taskinstance.py", line 768, in _execute_task
    result = _execute_callable(context=context, **execute_callable_kwargs)
             ^^^^^^^^^^^^^^^^^^^^^^^^^^^^^^^^^^^^^^^^^^^^^^^^^^^^^^^^^^^^^
  File "/home/airflow/.local/lib/python3.12/site-packages/airflow/models/taskinstance.py", line 734, in _execute_callable
    return ExecutionCallableRunner(
           ^^^^^^^^^^^^^^^^^^^^^^^^
  File "/home/airflow/.local/lib/python3.12/site-packages/airflow/utils/operator_helpers.py", line 252, in run
    return self.func(*args, **kwargs)
           ^^^^^^^^^^^^^^^^^^^^^^^^^^
  File "/home/airflow/.local/lib/python3.12/site-packages/airflow/models/baseoperator.py", line 424, in wrapper
    return func(self, *args, **kwargs)
           ^^^^^^^^^^^^^^^^^^^^^^^^^^^
  File "/home/airflow/.local/lib/python3.12/site-packages/airflow/providers/apache/spark/operators/spark_submit.py", line 157, in execute
    self._hook.submit(self._application)
  File "/home/airflow/.local/lib/python3.12/site-packages/airflow/providers/apache/spark/hooks/spark_submit.py", line 407, in submit
    self._process_spark_submit_log(iter(self._submit_sp.stdout))  # type: ignore
    ^^^^^^^^^^^^^^^^^^^^^^^^^^^^^^^^^^^^^^^^^^^^^^^^^^^^^^^^^^^^
  File "/home/airflow/.local/lib/python3.12/site-packages/airflow/providers/apache/spark/hooks/spark_submit.py", line 456, in _process_spark_submit_log
    for line in itr:
                ^^^
  File "/home/airflow/.local/lib/python3.12/site-packages/airflow/models/taskinstance.py", line 3097, in signal_handler
    raise AirflowTaskTerminated("Task received SIGTERM signal")
airflow.exceptions.AirflowTaskTerminated: Task received SIGTERM signal

During handling of the above exception, another exception occurred:

Traceback (most recent call last):
  File "/home/airflow/.local/lib/python3.12/site-packages/sqlalchemy/engine/base.py", line 3371, in _wrap_pool_connect
    return fn()
           ^^^^
  File "/home/airflow/.local/lib/python3.12/site-packages/sqlalchemy/pool/base.py", line 327, in connect
    return _ConnectionFairy._checkout(self)
           ^^^^^^^^^^^^^^^^^^^^^^^^^^^^^^^^
  File "/home/airflow/.local/lib/python3.12/site-packages/sqlalchemy/pool/base.py", line 894, in _checkout
    fairy = _ConnectionRecord.checkout(pool)
            ^^^^^^^^^^^^^^^^^^^^^^^^^^^^^^^^
  File "/home/airflow/.local/lib/python3.12/site-packages/sqlalchemy/pool/base.py", line 493, in checkout
    rec = pool._do_get()
          ^^^^^^^^^^^^^^
  File "/home/airflow/.local/lib/python3.12/site-packages/sqlalchemy/pool/impl.py", line 256, in _do_get
    return self._create_connection()
           ^^^^^^^^^^^^^^^^^^^^^^^^^
  File "/home/airflow/.local/lib/python3.12/site-packages/sqlalchemy/pool/base.py", line 273, in _create_connection
    return _ConnectionRecord(self)
           ^^^^^^^^^^^^^^^^^^^^^^^
  File "/home/airflow/.local/lib/python3.12/site-packages/sqlalchemy/pool/base.py", line 388, in __init__
    self.__connect()
  File "/home/airflow/.local/lib/python3.12/site-packages/sqlalchemy/pool/base.py", line 690, in __connect
    with util.safe_reraise():
         ^^^^^^^^^^^^^^^^^^^
  File "/home/airflow/.local/lib/python3.12/site-packages/sqlalchemy/util/langhelpers.py", line 70, in __exit__
    compat.raise_(
  File "/home/airflow/.local/lib/python3.12/site-packages/sqlalchemy/util/compat.py", line 211, in raise_
    raise exception
  File "/home/airflow/.local/lib/python3.12/site-packages/sqlalchemy/pool/base.py", line 686, in __connect
    self.dbapi_connection = connection = pool._invoke_creator(self)
                                         ^^^^^^^^^^^^^^^^^^^^^^^^^^
  File "/home/airflow/.local/lib/python3.12/site-packages/sqlalchemy/engine/create.py", line 574, in connect
    return dialect.connect(*cargs, **cparams)
           ^^^^^^^^^^^^^^^^^^^^^^^^^^^^^^^^^^
  File "/home/airflow/.local/lib/python3.12/site-packages/sqlalchemy/engine/default.py", line 598, in connect
    return self.dbapi.connect(*cargs, **cparams)
           ^^^^^^^^^^^^^^^^^^^^^^^^^^^^^^^^^^^^^
  File "/home/airflow/.local/lib/python3.12/site-packages/psycopg2/__init__.py", line 122, in connect
    conn = _connect(dsn, connection_factory=connection_factory, **kwasync)
           ^^^^^^^^^^^^^^^^^^^^^^^^^^^^^^^^^^^^^^^^^^^^^^^^^^^^^^^^^^^^^^^
psycopg2.OperationalError: could not translate host name "postgres" to address: Temporary failure in name resolution


The above exception was the direct cause of the following exception:

Traceback (most recent call last):
  File "/home/airflow/.local/lib/python3.12/site-packages/airflow/task/task_runner/standard_task_runner.py", line 117, in _start_by_fork
    ret = args.func(args, dag=self.dag)
          ^^^^^^^^^^^^^^^^^^^^^^^^^^^^^
  File "/home/airflow/.local/lib/python3.12/site-packages/airflow/cli/cli_config.py", line 49, in command
    return func(*args, **kwargs)
           ^^^^^^^^^^^^^^^^^^^^^
  File "/home/airflow/.local/lib/python3.12/site-packages/airflow/utils/cli.py", line 116, in wrapper
    return f(*args, **kwargs)
           ^^^^^^^^^^^^^^^^^^
  File "/home/airflow/.local/lib/python3.12/site-packages/airflow/cli/commands/task_command.py", line 483, in task_run
    task_return_code = _run_task_by_selected_method(args, _dag, ti)
                       ^^^^^^^^^^^^^^^^^^^^^^^^^^^^^^^^^^^^^^^^^^^^
  File "/home/airflow/.local/lib/python3.12/site-packages/airflow/cli/commands/task_command.py", line 256, in _run_task_by_selected_method
    return _run_raw_task(args, ti)
           ^^^^^^^^^^^^^^^^^^^^^^^
  File "/home/airflow/.local/lib/python3.12/site-packages/airflow/cli/commands/task_command.py", line 341, in _run_raw_task
    return ti._run_raw_task(
           ^^^^^^^^^^^^^^^^^
  File "/home/airflow/.local/lib/python3.12/site-packages/airflow/utils/session.py", line 97, in wrapper
    return func(*args, session=session, **kwargs)
           ^^^^^^^^^^^^^^^^^^^^^^^^^^^^^^^^^^^^^^
  File "/home/airflow/.local/lib/python3.12/site-packages/airflow/models/taskinstance.py", line 3006, in _run_raw_task
    return _run_raw_task(
           ^^^^^^^^^^^^^^
  File "/home/airflow/.local/lib/python3.12/site-packages/airflow/models/taskinstance.py", line 319, in _run_raw_task
    ti.refresh_from_db(lock_for_update=True, session=session)
  File "/home/airflow/.local/lib/python3.12/site-packages/airflow/utils/session.py", line 94, in wrapper
    return func(*args, **kwargs)
           ^^^^^^^^^^^^^^^^^^^^^
  File "/home/airflow/.local/lib/python3.12/site-packages/airflow/models/taskinstance.py", line 2360, in refresh_from_db
    _refresh_from_db(task_instance=self, session=session, lock_for_update=lock_for_update)
  File "/home/airflow/.local/lib/python3.12/site-packages/airflow/models/taskinstance.py", line 873, in _refresh_from_db
    ti = TaskInstance.get_task_instance(
         ^^^^^^^^^^^^^^^^^^^^^^^^^^^^^^^
  File "/home/airflow/.local/lib/python3.12/site-packages/airflow/api_internal/internal_api_call.py", line 166, in wrapper
    return func(*args, **kwargs)
           ^^^^^^^^^^^^^^^^^^^^^
  File "/home/airflow/.local/lib/python3.12/site-packages/airflow/utils/session.py", line 94, in wrapper
    return func(*args, **kwargs)
           ^^^^^^^^^^^^^^^^^^^^^
  File "/home/airflow/.local/lib/python3.12/site-packages/airflow/models/taskinstance.py", line 2342, in get_task_instance
    for attempt in run_with_db_retries(logger=cls.logger()):
                   ^^^^^^^^^^^^^^^^^^^^^^^^^^^^^^^^^^^^^^^^
  File "/home/airflow/.local/lib/python3.12/site-packages/tenacity/__init__.py", line 443, in __iter__
    do = self.iter(retry_state=retry_state)
         ^^^^^^^^^^^^^^^^^^^^^^^^^^^^^^^^^^
  File "/home/airflow/.local/lib/python3.12/site-packages/tenacity/__init__.py", line 376, in iter
    result = action(retry_state)
             ^^^^^^^^^^^^^^^^^^^
  File "/home/airflow/.local/lib/python3.12/site-packages/tenacity/__init__.py", line 418, in exc_check
    raise retry_exc.reraise()
          ^^^^^^^^^^^^^^^^^^^
  File "/home/airflow/.local/lib/python3.12/site-packages/tenacity/__init__.py", line 185, in reraise
    raise self.last_attempt.result()
          ^^^^^^^^^^^^^^^^^^^^^^^^^^
  File "/usr/local/lib/python3.12/concurrent/futures/_base.py", line 449, in result
    return self.__get_result()
           ^^^^^^^^^^^^^^^^^^^
  File "/usr/local/lib/python3.12/concurrent/futures/_base.py", line 401, in __get_result
    raise self._exception
  File "/home/airflow/.local/lib/python3.12/site-packages/airflow/models/taskinstance.py", line 2344, in get_task_instance
    return query.with_for_update().one_or_none()
           ^^^^^^^^^^^^^^^^^^^^^^^^^^^^^^^^^^^^^
  File "/home/airflow/.local/lib/python3.12/site-packages/sqlalchemy/orm/query.py", line 2850, in one_or_none
    return self._iter().one_or_none()
           ^^^^^^^^^^^^
  File "/home/airflow/.local/lib/python3.12/site-packages/sqlalchemy/orm/query.py", line 2916, in _iter
    result = self.session.execute(
             ^^^^^^^^^^^^^^^^^^^^^
  File "/home/airflow/.local/lib/python3.12/site-packages/sqlalchemy/orm/session.py", line 1716, in execute
    conn = self._connection_for_bind(bind)
           ^^^^^^^^^^^^^^^^^^^^^^^^^^^^^^^
  File "/home/airflow/.local/lib/python3.12/site-packages/sqlalchemy/orm/session.py", line 1555, in _connection_for_bind
    return self._transaction._connection_for_bind(
           ^^^^^^^^^^^^^^^^^^^^^^^^^^^^^^^^^^^^^^^
  File "/home/airflow/.local/lib/python3.12/site-packages/sqlalchemy/orm/session.py", line 750, in _connection_for_bind
    conn = bind.connect()
           ^^^^^^^^^^^^^^
  File "/home/airflow/.local/lib/python3.12/site-packages/sqlalchemy/future/engine.py", line 412, in connect
    return super(Engine, self).connect()
           ^^^^^^^^^^^^^^^^^^^^^^^^^^^^^
  File "/home/airflow/.local/lib/python3.12/site-packages/sqlalchemy/engine/base.py", line 3325, in connect
    return self._connection_cls(self, close_with_result=close_with_result)
           ^^^^^^^^^^^^^^^^^^^^^^^^^^^^^^^^^^^^^^^^^^^^^^^^^^^^^^^^^^^^^^^
  File "/home/airflow/.local/lib/python3.12/site-packages/sqlalchemy/engine/base.py", line 96, in __init__
    else engine.raw_connection()
         ^^^^^^^^^^^^^^^^^^^^^^^
  File "/home/airflow/.local/lib/python3.12/site-packages/sqlalchemy/engine/base.py", line 3404, in raw_connection
    return self._wrap_pool_connect(self.pool.connect, _connection)
           ^^^^^^^^^^^^^^^^^^^^^^^^^^^^^^^^^^^^^^^^^^^^^^^^^^^^^^^
  File "/home/airflow/.local/lib/python3.12/site-packages/sqlalchemy/engine/base.py", line 3374, in _wrap_pool_connect
    Connection._handle_dbapi_exception_noconnection(
  File "/home/airflow/.local/lib/python3.12/site-packages/sqlalchemy/engine/base.py", line 2208, in _handle_dbapi_exception_noconnection
    util.raise_(
  File "/home/airflow/.local/lib/python3.12/site-packages/sqlalchemy/util/compat.py", line 211, in raise_
    raise exception
  File "/home/airflow/.local/lib/python3.12/site-packages/sqlalchemy/engine/base.py", line 3371, in _wrap_pool_connect
    return fn()
           ^^^^
  File "/home/airflow/.local/lib/python3.12/site-packages/sqlalchemy/pool/base.py", line 327, in connect
    return _ConnectionFairy._checkout(self)
           ^^^^^^^^^^^^^^^^^^^^^^^^^^^^^^^^
  File "/home/airflow/.local/lib/python3.12/site-packages/sqlalchemy/pool/base.py", line 894, in _checkout
    fairy = _ConnectionRecord.checkout(pool)
            ^^^^^^^^^^^^^^^^^^^^^^^^^^^^^^^^
  File "/home/airflow/.local/lib/python3.12/site-packages/sqlalchemy/pool/base.py", line 493, in checkout
    rec = pool._do_get()
          ^^^^^^^^^^^^^^
  File "/home/airflow/.local/lib/python3.12/site-packages/sqlalchemy/pool/impl.py", line 256, in _do_get
    return self._create_connection()
           ^^^^^^^^^^^^^^^^^^^^^^^^^
  File "/home/airflow/.local/lib/python3.12/site-packages/sqlalchemy/pool/base.py", line 273, in _create_connection
    return _ConnectionRecord(self)
           ^^^^^^^^^^^^^^^^^^^^^^^
  File "/home/airflow/.local/lib/python3.12/site-packages/sqlalchemy/pool/base.py", line 388, in __init__
    self.__connect()
  File "/home/airflow/.local/lib/python3.12/site-packages/sqlalchemy/pool/base.py", line 690, in __connect
    with util.safe_reraise():
         ^^^^^^^^^^^^^^^^^^^
  File "/home/airflow/.local/lib/python3.12/site-packages/sqlalchemy/util/langhelpers.py", line 70, in __exit__
    compat.raise_(
  File "/home/airflow/.local/lib/python3.12/site-packages/sqlalchemy/util/compat.py", line 211, in raise_
    raise exception
  File "/home/airflow/.local/lib/python3.12/site-packages/sqlalchemy/pool/base.py", line 686, in __connect
    self.dbapi_connection = connection = pool._invoke_creator(self)
                                         ^^^^^^^^^^^^^^^^^^^^^^^^^^
  File "/home/airflow/.local/lib/python3.12/site-packages/sqlalchemy/engine/create.py", line 574, in connect
    return dialect.connect(*cargs, **cparams)
           ^^^^^^^^^^^^^^^^^^^^^^^^^^^^^^^^^^
  File "/home/airflow/.local/lib/python3.12/site-packages/sqlalchemy/engine/default.py", line 598, in connect
    return self.dbapi.connect(*cargs, **cparams)
           ^^^^^^^^^^^^^^^^^^^^^^^^^^^^^^^^^^^^^
  File "/home/airflow/.local/lib/python3.12/site-packages/psycopg2/__init__.py", line 122, in connect
    conn = _connect(dsn, connection_factory=connection_factory, **kwasync)
           ^^^^^^^^^^^^^^^^^^^^^^^^^^^^^^^^^^^^^^^^^^^^^^^^^^^^^^^^^^^^^^^
sqlalchemy.exc.OperationalError: (psycopg2.OperationalError) could not translate host name "postgres" to address: Temporary failure in name resolution

(Background on this error at: https://sqlalche.me/e/14/e3q8)
[2025-03-14T19:00:03.467+0000] {process_utils.py:80} INFO - Process psutil.Process(pid=327, status='terminated', started='18:53:37') (327) terminated with exit code None
[2025-03-14T19:00:03.471+0000] {process_utils.py:80} INFO - Process psutil.Process(pid=322, status='terminated', exitcode=1, started='18:53:36') (322) terminated with exit code 1
