[2025-03-15T18:33:19.461+0000] {local_task_job_runner.py:123} INFO - ::group::Pre task execution logs
[2025-03-15T18:33:19.506+0000] {taskinstance.py:2614} INFO - Dependencies all met for dep_context=non-requeueable deps ti=<TaskInstance: solar_energy_crops_pipeline.first_task manual__2025-03-15T18:20:02.677832+00:00 [queued]>
[2025-03-15T18:33:19.525+0000] {taskinstance.py:2614} INFO - Dependencies all met for dep_context=requeueable deps ti=<TaskInstance: solar_energy_crops_pipeline.first_task manual__2025-03-15T18:20:02.677832+00:00 [queued]>
[2025-03-15T18:33:19.527+0000] {taskinstance.py:2867} INFO - Starting attempt 2 of 2
[2025-03-15T18:33:19.550+0000] {taskinstance.py:2890} INFO - Executing <Task(SparkSubmitOperator): first_task> on 2025-03-15 18:20:02.677832+00:00
[2025-03-15T18:33:19.560+0000] {standard_task_runner.py:104} INFO - Running: ['***', 'tasks', 'run', 'solar_energy_crops_pipeline', 'first_task', 'manual__2025-03-15T18:20:02.677832+00:00', '--job-id', '115', '--raw', '--subdir', 'DAGS_FOLDER/mainDag.py', '--cfg-path', '/tmp/tmp91wrfrpy']
[2025-03-15T18:33:19.565+0000] {standard_task_runner.py:105} INFO - Job 115: Subtask first_task
[2025-03-15T18:33:19.559+0000] {warnings.py:112} WARNING - /home/***/.local/lib/python3.12/site-packages/***/task/task_runner/standard_task_runner.py:70: DeprecationWarning: This process (pid=278) is multi-threaded, use of fork() may lead to deadlocks in the child.
  pid = os.fork()

[2025-03-15T18:33:19.580+0000] {standard_task_runner.py:72} INFO - Started process 279 to run task
[2025-03-15T18:33:19.662+0000] {task_command.py:467} INFO - Running <TaskInstance: solar_energy_crops_pipeline.first_task manual__2025-03-15T18:20:02.677832+00:00 [running]> on host 26a73488cd9b
[2025-03-15T18:33:19.789+0000] {taskinstance.py:3134} INFO - Exporting env vars: AIRFLOW_CTX_DAG_OWNER='***' AIRFLOW_CTX_DAG_ID='solar_energy_crops_pipeline' AIRFLOW_CTX_TASK_ID='first_task' AIRFLOW_CTX_EXECUTION_DATE='2025-03-15T18:20:02.677832+00:00' AIRFLOW_CTX_TRY_NUMBER='2' AIRFLOW_CTX_DAG_RUN_ID='manual__2025-03-15T18:20:02.677832+00:00'
[2025-03-15T18:33:19.791+0000] {taskinstance.py:732} INFO - ::endgroup::
[2025-03-15T18:33:19.878+0000] {base.py:84} INFO - Retrieving connection 'spark_mm'
[2025-03-15T18:33:19.882+0000] {spark_submit.py:335} INFO - Spark-Submit cmd: spark-submit --master spark://spark-master:7077 --name arrow-spark jobs/Script1.py
[2025-03-15T18:33:27.234+0000] {spark_submit.py:488} INFO - 25/03/15 18:33:27 INFO SparkContext: Running Spark version 3.5.5
[2025-03-15T18:33:27.237+0000] {spark_submit.py:488} INFO - 25/03/15 18:33:27 INFO SparkContext: OS info Linux, 5.15.167.4-microsoft-standard-WSL2, amd64
[2025-03-15T18:33:27.238+0000] {spark_submit.py:488} INFO - 25/03/15 18:33:27 INFO SparkContext: Java version 17.0.14
[2025-03-15T18:33:27.337+0000] {spark_submit.py:488} INFO - 25/03/15 18:33:27 WARN NativeCodeLoader: Unable to load native-hadoop library for your platform... using builtin-java classes where applicable
[2025-03-15T18:33:27.528+0000] {spark_submit.py:488} INFO - 25/03/15 18:33:27 INFO ResourceUtils: ==============================================================
[2025-03-15T18:33:27.529+0000] {spark_submit.py:488} INFO - 25/03/15 18:33:27 INFO ResourceUtils: No custom resources configured for spark.driver.
[2025-03-15T18:33:27.530+0000] {spark_submit.py:488} INFO - 25/03/15 18:33:27 INFO ResourceUtils: ==============================================================
[2025-03-15T18:33:27.531+0000] {spark_submit.py:488} INFO - 25/03/15 18:33:27 INFO SparkContext: Submitted application: PythonWordCount
[2025-03-15T18:33:27.612+0000] {spark_submit.py:488} INFO - 25/03/15 18:33:27 INFO ResourceProfile: Default ResourceProfile created, executor resources: Map(memory -> name: memory, amount: 1024, script: , vendor: , offHeap -> name: offHeap, amount: 0, script: , vendor: ), task resources: Map(cpus -> name: cpus, amount: 1.0)
[2025-03-15T18:33:27.623+0000] {spark_submit.py:488} INFO - 25/03/15 18:33:27 INFO ResourceProfile: Limiting resource is cpu
[2025-03-15T18:33:27.625+0000] {spark_submit.py:488} INFO - 25/03/15 18:33:27 INFO ResourceProfileManager: Added ResourceProfile id: 0
[2025-03-15T18:33:27.809+0000] {spark_submit.py:488} INFO - 25/03/15 18:33:27 INFO SecurityManager: Changing view acls to: ***
[2025-03-15T18:33:27.810+0000] {spark_submit.py:488} INFO - 25/03/15 18:33:27 INFO SecurityManager: Changing modify acls to: ***
[2025-03-15T18:33:27.812+0000] {spark_submit.py:488} INFO - 25/03/15 18:33:27 INFO SecurityManager: Changing view acls groups to:
[2025-03-15T18:33:27.813+0000] {spark_submit.py:488} INFO - 25/03/15 18:33:27 INFO SecurityManager: Changing modify acls groups to:
[2025-03-15T18:33:27.814+0000] {spark_submit.py:488} INFO - 25/03/15 18:33:27 INFO SecurityManager: SecurityManager: authentication disabled; ui acls disabled; users with view permissions: ***; groups with view permissions: EMPTY; users with modify permissions: ***; groups with modify permissions: EMPTY
[2025-03-15T18:33:28.417+0000] {spark_submit.py:488} INFO - 25/03/15 18:33:28 INFO Utils: Successfully started service 'sparkDriver' on port 39621.
[2025-03-15T18:33:28.525+0000] {spark_submit.py:488} INFO - 25/03/15 18:33:28 INFO SparkEnv: Registering MapOutputTracker
[2025-03-15T18:33:28.630+0000] {spark_submit.py:488} INFO - 25/03/15 18:33:28 INFO SparkEnv: Registering BlockManagerMaster
[2025-03-15T18:33:28.713+0000] {spark_submit.py:488} INFO - 25/03/15 18:33:28 INFO BlockManagerMasterEndpoint: Using org.apache.spark.storage.DefaultTopologyMapper for getting topology information
[2025-03-15T18:33:28.714+0000] {spark_submit.py:488} INFO - 25/03/15 18:33:28 INFO BlockManagerMasterEndpoint: BlockManagerMasterEndpoint up
[2025-03-15T18:33:28.718+0000] {spark_submit.py:488} INFO - 25/03/15 18:33:28 INFO SparkEnv: Registering BlockManagerMasterHeartbeat
[2025-03-15T18:33:28.802+0000] {spark_submit.py:488} INFO - 25/03/15 18:33:28 INFO DiskBlockManager: Created local directory at /tmp/blockmgr-d9d58a8d-3afa-4e86-9b07-582531e7491d
[2025-03-15T18:33:28.818+0000] {spark_submit.py:488} INFO - 25/03/15 18:33:28 INFO MemoryStore: MemoryStore started with capacity 413.9 MiB
[2025-03-15T18:33:28.891+0000] {spark_submit.py:488} INFO - 25/03/15 18:33:28 INFO SparkEnv: Registering OutputCommitCoordinator
[2025-03-15T18:33:29.146+0000] {spark_submit.py:488} INFO - 25/03/15 18:33:29 INFO JettyUtils: Start Jetty 0.0.0.0:4040 for SparkUI
[2025-03-15T18:33:29.330+0000] {spark_submit.py:488} INFO - 25/03/15 18:33:29 INFO Utils: Successfully started service 'SparkUI' on port 4040.
[2025-03-15T18:33:29.600+0000] {spark_submit.py:488} INFO - 25/03/15 18:33:29 INFO StandaloneAppClient$ClientEndpoint: Connecting to master spark://spark-master:7077...
[2025-03-15T18:33:29.703+0000] {spark_submit.py:488} INFO - 25/03/15 18:33:29 INFO TransportClientFactory: Successfully created connection to spark-master/172.18.0.4:7077 after 75 ms (0 ms spent in bootstraps)
[2025-03-15T18:33:29.874+0000] {spark_submit.py:488} INFO - 25/03/15 18:33:29 INFO StandaloneSchedulerBackend: Connected to Spark cluster with app ID app-20250315183329-0001
[2025-03-15T18:33:29.890+0000] {spark_submit.py:488} INFO - 25/03/15 18:33:29 INFO Utils: Successfully started service 'org.apache.spark.network.netty.NettyBlockTransferService' on port 34329.
[2025-03-15T18:33:29.891+0000] {spark_submit.py:488} INFO - 25/03/15 18:33:29 INFO NettyBlockTransferService: Server created on 26a73488cd9b:34329
[2025-03-15T18:33:29.891+0000] {spark_submit.py:488} INFO - 25/03/15 18:33:29 INFO StandaloneAppClient$ClientEndpoint: Executor added: app-20250315183329-0001/0 on worker-20250315181643-172.18.0.6-39107 (172.18.0.6:39107) with 2 core(s)
[2025-03-15T18:33:29.893+0000] {spark_submit.py:488} INFO - 25/03/15 18:33:29 INFO StandaloneSchedulerBackend: Granted executor ID app-20250315183329-0001/0 on hostPort 172.18.0.6:39107 with 2 core(s), 1024.0 MiB RAM
[2025-03-15T18:33:29.894+0000] {spark_submit.py:488} INFO - 25/03/15 18:33:29 INFO BlockManager: Using org.apache.spark.storage.RandomBlockReplicationPolicy for block replication policy
[2025-03-15T18:33:29.902+0000] {spark_submit.py:488} INFO - 25/03/15 18:33:29 INFO BlockManagerMaster: Registering BlockManager BlockManagerId(driver, 26a73488cd9b, 34329, None)
[2025-03-15T18:33:29.907+0000] {spark_submit.py:488} INFO - 25/03/15 18:33:29 INFO BlockManagerMasterEndpoint: Registering block manager 26a73488cd9b:34329 with 413.9 MiB RAM, BlockManagerId(driver, 26a73488cd9b, 34329, None)
[2025-03-15T18:33:29.910+0000] {spark_submit.py:488} INFO - 25/03/15 18:33:29 INFO BlockManagerMaster: Registered BlockManager BlockManagerId(driver, 26a73488cd9b, 34329, None)
[2025-03-15T18:33:29.912+0000] {spark_submit.py:488} INFO - 25/03/15 18:33:29 INFO BlockManager: Initialized BlockManager: BlockManagerId(driver, 26a73488cd9b, 34329, None)
[2025-03-15T18:33:30.136+0000] {spark_submit.py:488} INFO - 25/03/15 18:33:30 INFO StandaloneAppClient$ClientEndpoint: Executor updated: app-20250315183329-0001/0 is now RUNNING
[2025-03-15T18:33:30.396+0000] {spark_submit.py:488} INFO - 25/03/15 18:33:30 INFO StandaloneSchedulerBackend: SchedulerBackend is ready for scheduling beginning after reached minRegisteredResourcesRatio: 0.0
[2025-03-15T18:33:31.410+0000] {spark_submit.py:488} INFO - 25/03/15 18:33:31 INFO SparkContext: Starting job: collect at /opt/***/jobs/Script1.py:21
[2025-03-15T18:33:31.501+0000] {spark_submit.py:488} INFO - 25/03/15 18:33:31 INFO DAGScheduler: Registering RDD 2 (reduceByKey at /opt/***/jobs/Script1.py:19) as input to shuffle 0
[2025-03-15T18:33:31.509+0000] {spark_submit.py:488} INFO - 25/03/15 18:33:31 INFO DAGScheduler: Got job 0 (collect at /opt/***/jobs/Script1.py:21) with 2 output partitions
[2025-03-15T18:33:31.510+0000] {spark_submit.py:488} INFO - 25/03/15 18:33:31 INFO DAGScheduler: Final stage: ResultStage 1 (collect at /opt/***/jobs/Script1.py:21)
[2025-03-15T18:33:31.511+0000] {spark_submit.py:488} INFO - 25/03/15 18:33:31 INFO DAGScheduler: Parents of final stage: List(ShuffleMapStage 0)
[2025-03-15T18:33:31.513+0000] {spark_submit.py:488} INFO - 25/03/15 18:33:31 INFO DAGScheduler: Missing parents: List(ShuffleMapStage 0)
[2025-03-15T18:33:31.518+0000] {spark_submit.py:488} INFO - 25/03/15 18:33:31 INFO DAGScheduler: Submitting ShuffleMapStage 0 (PairwiseRDD[2] at reduceByKey at /opt/***/jobs/Script1.py:19), which has no missing parents
[2025-03-15T18:33:31.764+0000] {spark_submit.py:488} INFO - 25/03/15 18:33:31 INFO MemoryStore: Block broadcast_0 stored as values in memory (estimated size 10.9 KiB, free 413.9 MiB)
[2025-03-15T18:33:31.858+0000] {spark_submit.py:488} INFO - 25/03/15 18:33:31 INFO MemoryStore: Block broadcast_0_piece0 stored as bytes in memory (estimated size 7.0 KiB, free 413.9 MiB)
[2025-03-15T18:33:31.863+0000] {spark_submit.py:488} INFO - 25/03/15 18:33:31 INFO BlockManagerInfo: Added broadcast_0_piece0 in memory on 26a73488cd9b:34329 (size: 7.0 KiB, free: 413.9 MiB)
[2025-03-15T18:33:31.872+0000] {spark_submit.py:488} INFO - 25/03/15 18:33:31 INFO SparkContext: Created broadcast 0 from broadcast at DAGScheduler.scala:1585
[2025-03-15T18:33:31.925+0000] {spark_submit.py:488} INFO - 25/03/15 18:33:31 INFO DAGScheduler: Submitting 2 missing tasks from ShuffleMapStage 0 (PairwiseRDD[2] at reduceByKey at /opt/***/jobs/Script1.py:19) (first 15 tasks are for partitions Vector(0, 1))
[2025-03-15T18:33:31.928+0000] {spark_submit.py:488} INFO - 25/03/15 18:33:31 INFO TaskSchedulerImpl: Adding task set 0.0 with 2 tasks resource profile 0
[2025-03-15T18:33:45.835+0000] {job.py:239} ERROR - Job heartbeat failed with error
Traceback (most recent call last):
  File "/home/airflow/.local/lib/python3.12/site-packages/sqlalchemy/engine/base.py", line 3371, in _wrap_pool_connect
    return fn()
           ^^^^
  File "/home/airflow/.local/lib/python3.12/site-packages/sqlalchemy/pool/base.py", line 327, in connect
    return _ConnectionFairy._checkout(self)
           ^^^^^^^^^^^^^^^^^^^^^^^^^^^^^^^^
  File "/home/airflow/.local/lib/python3.12/site-packages/sqlalchemy/pool/base.py", line 894, in _checkout
    fairy = _ConnectionRecord.checkout(pool)
            ^^^^^^^^^^^^^^^^^^^^^^^^^^^^^^^^
  File "/home/airflow/.local/lib/python3.12/site-packages/sqlalchemy/pool/base.py", line 493, in checkout
    rec = pool._do_get()
          ^^^^^^^^^^^^^^
  File "/home/airflow/.local/lib/python3.12/site-packages/sqlalchemy/pool/impl.py", line 256, in _do_get
    return self._create_connection()
           ^^^^^^^^^^^^^^^^^^^^^^^^^
  File "/home/airflow/.local/lib/python3.12/site-packages/sqlalchemy/pool/base.py", line 273, in _create_connection
    return _ConnectionRecord(self)
           ^^^^^^^^^^^^^^^^^^^^^^^
  File "/home/airflow/.local/lib/python3.12/site-packages/sqlalchemy/pool/base.py", line 388, in __init__
    self.__connect()
  File "/home/airflow/.local/lib/python3.12/site-packages/sqlalchemy/pool/base.py", line 690, in __connect
    with util.safe_reraise():
         ^^^^^^^^^^^^^^^^^^^
  File "/home/airflow/.local/lib/python3.12/site-packages/sqlalchemy/util/langhelpers.py", line 70, in __exit__
    compat.raise_(
  File "/home/airflow/.local/lib/python3.12/site-packages/sqlalchemy/util/compat.py", line 211, in raise_
    raise exception
  File "/home/airflow/.local/lib/python3.12/site-packages/sqlalchemy/pool/base.py", line 686, in __connect
    self.dbapi_connection = connection = pool._invoke_creator(self)
                                         ^^^^^^^^^^^^^^^^^^^^^^^^^^
  File "/home/airflow/.local/lib/python3.12/site-packages/sqlalchemy/engine/create.py", line 574, in connect
    return dialect.connect(*cargs, **cparams)
           ^^^^^^^^^^^^^^^^^^^^^^^^^^^^^^^^^^
  File "/home/airflow/.local/lib/python3.12/site-packages/sqlalchemy/engine/default.py", line 598, in connect
    return self.dbapi.connect(*cargs, **cparams)
           ^^^^^^^^^^^^^^^^^^^^^^^^^^^^^^^^^^^^^
  File "/home/airflow/.local/lib/python3.12/site-packages/psycopg2/__init__.py", line 122, in connect
    conn = _connect(dsn, connection_factory=connection_factory, **kwasync)
           ^^^^^^^^^^^^^^^^^^^^^^^^^^^^^^^^^^^^^^^^^^^^^^^^^^^^^^^^^^^^^^^
psycopg2.OperationalError: could not translate host name "postgres" to address: Temporary failure in name resolution


The above exception was the direct cause of the following exception:

Traceback (most recent call last):
  File "/home/airflow/.local/lib/python3.12/site-packages/airflow/jobs/job.py", line 233, in heartbeat
    heartbeat_callback(session)
  File "/home/airflow/.local/lib/python3.12/site-packages/airflow/utils/session.py", line 94, in wrapper
    return func(*args, **kwargs)
           ^^^^^^^^^^^^^^^^^^^^^
  File "/home/airflow/.local/lib/python3.12/site-packages/airflow/jobs/local_task_job_runner.py", line 284, in heartbeat_callback
    self.task_instance.refresh_from_db()
  File "/home/airflow/.local/lib/python3.12/site-packages/airflow/utils/session.py", line 97, in wrapper
    return func(*args, session=session, **kwargs)
           ^^^^^^^^^^^^^^^^^^^^^^^^^^^^^^^^^^^^^^
  File "/home/airflow/.local/lib/python3.12/site-packages/airflow/models/taskinstance.py", line 2360, in refresh_from_db
    _refresh_from_db(task_instance=self, session=session, lock_for_update=lock_for_update)
  File "/home/airflow/.local/lib/python3.12/site-packages/airflow/models/taskinstance.py", line 873, in _refresh_from_db
    ti = TaskInstance.get_task_instance(
         ^^^^^^^^^^^^^^^^^^^^^^^^^^^^^^^
  File "/home/airflow/.local/lib/python3.12/site-packages/airflow/api_internal/internal_api_call.py", line 166, in wrapper
    return func(*args, **kwargs)
           ^^^^^^^^^^^^^^^^^^^^^
  File "/home/airflow/.local/lib/python3.12/site-packages/airflow/utils/session.py", line 94, in wrapper
    return func(*args, **kwargs)
           ^^^^^^^^^^^^^^^^^^^^^
  File "/home/airflow/.local/lib/python3.12/site-packages/airflow/models/taskinstance.py", line 2346, in get_task_instance
    return query.one_or_none()
           ^^^^^^^^^^^^^^^^^^^
  File "/home/airflow/.local/lib/python3.12/site-packages/sqlalchemy/orm/query.py", line 2850, in one_or_none
    return self._iter().one_or_none()
           ^^^^^^^^^^^^
  File "/home/airflow/.local/lib/python3.12/site-packages/sqlalchemy/orm/query.py", line 2916, in _iter
    result = self.session.execute(
             ^^^^^^^^^^^^^^^^^^^^^
  File "/home/airflow/.local/lib/python3.12/site-packages/sqlalchemy/orm/session.py", line 1716, in execute
    conn = self._connection_for_bind(bind)
           ^^^^^^^^^^^^^^^^^^^^^^^^^^^^^^^
  File "/home/airflow/.local/lib/python3.12/site-packages/sqlalchemy/orm/session.py", line 1555, in _connection_for_bind
    return self._transaction._connection_for_bind(
           ^^^^^^^^^^^^^^^^^^^^^^^^^^^^^^^^^^^^^^^
  File "/home/airflow/.local/lib/python3.12/site-packages/sqlalchemy/orm/session.py", line 750, in _connection_for_bind
    conn = bind.connect()
           ^^^^^^^^^^^^^^
  File "/home/airflow/.local/lib/python3.12/site-packages/sqlalchemy/future/engine.py", line 412, in connect
    return super(Engine, self).connect()
           ^^^^^^^^^^^^^^^^^^^^^^^^^^^^^
  File "/home/airflow/.local/lib/python3.12/site-packages/sqlalchemy/engine/base.py", line 3325, in connect
    return self._connection_cls(self, close_with_result=close_with_result)
           ^^^^^^^^^^^^^^^^^^^^^^^^^^^^^^^^^^^^^^^^^^^^^^^^^^^^^^^^^^^^^^^
  File "/home/airflow/.local/lib/python3.12/site-packages/sqlalchemy/engine/base.py", line 96, in __init__
    else engine.raw_connection()
         ^^^^^^^^^^^^^^^^^^^^^^^
  File "/home/airflow/.local/lib/python3.12/site-packages/sqlalchemy/engine/base.py", line 3404, in raw_connection
    return self._wrap_pool_connect(self.pool.connect, _connection)
           ^^^^^^^^^^^^^^^^^^^^^^^^^^^^^^^^^^^^^^^^^^^^^^^^^^^^^^^
  File "/home/airflow/.local/lib/python3.12/site-packages/sqlalchemy/engine/base.py", line 3374, in _wrap_pool_connect
    Connection._handle_dbapi_exception_noconnection(
  File "/home/airflow/.local/lib/python3.12/site-packages/sqlalchemy/engine/base.py", line 2208, in _handle_dbapi_exception_noconnection
    util.raise_(
  File "/home/airflow/.local/lib/python3.12/site-packages/sqlalchemy/util/compat.py", line 211, in raise_
    raise exception
  File "/home/airflow/.local/lib/python3.12/site-packages/sqlalchemy/engine/base.py", line 3371, in _wrap_pool_connect
    return fn()
           ^^^^
  File "/home/airflow/.local/lib/python3.12/site-packages/sqlalchemy/pool/base.py", line 327, in connect
    return _ConnectionFairy._checkout(self)
           ^^^^^^^^^^^^^^^^^^^^^^^^^^^^^^^^
  File "/home/airflow/.local/lib/python3.12/site-packages/sqlalchemy/pool/base.py", line 894, in _checkout
    fairy = _ConnectionRecord.checkout(pool)
            ^^^^^^^^^^^^^^^^^^^^^^^^^^^^^^^^
  File "/home/airflow/.local/lib/python3.12/site-packages/sqlalchemy/pool/base.py", line 493, in checkout
    rec = pool._do_get()
          ^^^^^^^^^^^^^^
  File "/home/airflow/.local/lib/python3.12/site-packages/sqlalchemy/pool/impl.py", line 256, in _do_get
    return self._create_connection()
           ^^^^^^^^^^^^^^^^^^^^^^^^^
  File "/home/airflow/.local/lib/python3.12/site-packages/sqlalchemy/pool/base.py", line 273, in _create_connection
    return _ConnectionRecord(self)
           ^^^^^^^^^^^^^^^^^^^^^^^
  File "/home/airflow/.local/lib/python3.12/site-packages/sqlalchemy/pool/base.py", line 388, in __init__
    self.__connect()
  File "/home/airflow/.local/lib/python3.12/site-packages/sqlalchemy/pool/base.py", line 690, in __connect
    with util.safe_reraise():
         ^^^^^^^^^^^^^^^^^^^
  File "/home/airflow/.local/lib/python3.12/site-packages/sqlalchemy/util/langhelpers.py", line 70, in __exit__
    compat.raise_(
  File "/home/airflow/.local/lib/python3.12/site-packages/sqlalchemy/util/compat.py", line 211, in raise_
    raise exception
  File "/home/airflow/.local/lib/python3.12/site-packages/sqlalchemy/pool/base.py", line 686, in __connect
    self.dbapi_connection = connection = pool._invoke_creator(self)
                                         ^^^^^^^^^^^^^^^^^^^^^^^^^^
  File "/home/airflow/.local/lib/python3.12/site-packages/sqlalchemy/engine/create.py", line 574, in connect
    return dialect.connect(*cargs, **cparams)
           ^^^^^^^^^^^^^^^^^^^^^^^^^^^^^^^^^^
  File "/home/airflow/.local/lib/python3.12/site-packages/sqlalchemy/engine/default.py", line 598, in connect
    return self.dbapi.connect(*cargs, **cparams)
           ^^^^^^^^^^^^^^^^^^^^^^^^^^^^^^^^^^^^^
  File "/home/airflow/.local/lib/python3.12/site-packages/psycopg2/__init__.py", line 122, in connect
    conn = _connect(dsn, connection_factory=connection_factory, **kwasync)
           ^^^^^^^^^^^^^^^^^^^^^^^^^^^^^^^^^^^^^^^^^^^^^^^^^^^^^^^^^^^^^^^
sqlalchemy.exc.OperationalError: (psycopg2.OperationalError) could not translate host name "postgres" to address: Temporary failure in name resolution

(Background on this error at: https://sqlalche.me/e/14/e3q8)
[2025-03-15T18:33:46.649+0000] {job.py:254} ERROR - Job heartbeat failed with error. Scheduler is in unhealthy state
[2025-03-15T18:33:49.039+0000] {spark_submit.py:488} INFO - 25/03/15 18:33:49 WARN TaskSchedulerImpl: Initial job has not accepted any resources; check your cluster UI to ensure that workers are registered and have sufficient resources
[2025-03-15T18:34:02.417+0000] {spark_submit.py:488} INFO - 25/03/15 18:34:02 WARN TaskSchedulerImpl: Initial job has not accepted any resources; check your cluster UI to ensure that workers are registered and have sufficient resources
[2025-03-15T18:34:17.964+0000] {spark_submit.py:488} INFO - 25/03/15 18:34:17 WARN TaskSchedulerImpl: Initial job has not accepted any resources; check your cluster UI to ensure that workers are registered and have sufficient resources
[2025-03-15T18:34:33.299+0000] {spark_submit.py:488} INFO - 25/03/15 18:34:32 WARN TaskSchedulerImpl: Initial job has not accepted any resources; check your cluster UI to ensure that workers are registered and have sufficient resources
[2025-03-15T18:34:37.390+0000] {job.py:254} ERROR - Job heartbeat failed with error. Scheduler is in unhealthy state
[2025-03-15T18:34:48.377+0000] {spark_submit.py:488} INFO - 25/03/15 18:34:47 WARN TaskSchedulerImpl: Initial job has not accepted any resources; check your cluster UI to ensure that workers are registered and have sufficient resources
[2025-03-15T18:35:02.107+0000] {spark_submit.py:488} INFO - 25/03/15 18:35:02 WARN TaskSchedulerImpl: Initial job has not accepted any resources; check your cluster UI to ensure that workers are registered and have sufficient resources
[2025-03-15T18:35:04.598+0000] {spark_submit.py:488} INFO - 25/03/15 18:35:04 INFO AsyncEventQueue: Process of event SparkListenerExecutorMetricsUpdate(driver,WrappedArray(),Map((-1,-1) -> org.apache.spark.executor.ExecutorMetrics@7838ae6b)) by listener AppStatusListener took 2.526300883s.
[2025-03-15T18:35:17.666+0000] {spark_submit.py:488} INFO - 25/03/15 18:35:17 WARN TaskSchedulerImpl: Initial job has not accepted any resources; check your cluster UI to ensure that workers are registered and have sufficient resources
[2025-03-15T18:35:22.702+0000] {job.py:254} ERROR - Job heartbeat failed with error. Scheduler is in unhealthy state
[2025-03-15T18:35:32.333+0000] {spark_submit.py:488} INFO - 25/03/15 18:35:32 WARN TaskSchedulerImpl: Initial job has not accepted any resources; check your cluster UI to ensure that workers are registered and have sufficient resources
[2025-03-15T18:35:47.620+0000] {spark_submit.py:488} INFO - 25/03/15 18:35:47 WARN TaskSchedulerImpl: Initial job has not accepted any resources; check your cluster UI to ensure that workers are registered and have sufficient resources
[2025-03-15T18:35:49.122+0000] {spark_submit.py:488} INFO - 25/03/15 18:35:48 INFO AsyncEventQueue: Process of event SparkListenerExecutorMetricsUpdate(driver,WrappedArray(),Map((-1,-1) -> org.apache.spark.executor.ExecutorMetrics@61f47c04)) by listener AppStatusListener took 2.483750252s.
[2025-03-15T18:35:59.615+0000] {job.py:254} ERROR - Job heartbeat failed with error. Scheduler is in unhealthy state
[2025-03-15T18:36:02.063+0000] {spark_submit.py:488} INFO - 25/03/15 18:36:02 WARN TaskSchedulerImpl: Initial job has not accepted any resources; check your cluster UI to ensure that workers are registered and have sufficient resources
[2025-03-15T18:36:17.106+0000] {spark_submit.py:488} INFO - 25/03/15 18:36:17 WARN TaskSchedulerImpl: Initial job has not accepted any resources; check your cluster UI to ensure that workers are registered and have sufficient resources
[2025-03-15T18:36:32.146+0000] {spark_submit.py:488} INFO - 25/03/15 18:36:32 WARN TaskSchedulerImpl: Initial job has not accepted any resources; check your cluster UI to ensure that workers are registered and have sufficient resources
[2025-03-15T18:36:36.216+0000] {spark_submit.py:488} INFO - 25/03/15 18:36:36 INFO StandaloneSchedulerBackend$StandaloneDriverEndpoint: Registered executor NettyRpcEndpointRef(spark-client://Executor) (172.18.0.6:34204) with ID 0,  ResourceProfileId 0
[2025-03-15T18:36:36.749+0000] {job.py:254} ERROR - Job heartbeat failed with error. Scheduler is in unhealthy state
[2025-03-15T18:36:47.757+0000] {spark_submit.py:488} INFO - 25/03/15 18:36:47 WARN TaskSchedulerImpl: Initial job has not accepted any resources; check your cluster UI to ensure that workers are registered and have sufficient resources
[2025-03-15T18:37:02.430+0000] {spark_submit.py:488} INFO - 25/03/15 18:37:02 WARN TaskSchedulerImpl: Initial job has not accepted any resources; check your cluster UI to ensure that workers are registered and have sufficient resources
[2025-03-15T18:37:18.830+0000] {spark_submit.py:488} INFO - 25/03/15 18:37:17 WARN TaskSchedulerImpl: Initial job has not accepted any resources; check your cluster UI to ensure that workers are registered and have sufficient resources
[2025-03-15T18:37:23.129+0000] {spark_submit.py:488} INFO - 25/03/15 18:37:19 INFO AsyncEventQueue: Process of event SparkListenerExecutorAdded(1742063806912,0,org.apache.spark.scheduler.cluster.ExecutorData@ccdb28b) by listener HeartbeatReceiver took 6.192583817s.
[2025-03-15T18:37:38.123+0000] {spark_submit.py:488} INFO - 25/03/15 18:37:32 WARN TaskSchedulerImpl: Initial job has not accepted any resources; check your cluster UI to ensure that workers are registered and have sufficient resources
[2025-03-15T18:37:22.213+0000] {job.py:254} ERROR - Job heartbeat failed with error. Scheduler is in unhealthy state
[2025-03-15T18:37:54.222+0000] {spark_submit.py:488} INFO - 25/03/15 18:37:38 INFO AsyncEventQueue: Process of event SparkListenerExecutorAdded(1742063806912,0,org.apache.spark.scheduler.cluster.ExecutorData@ccdb28b) by listener AppStatusListener took 35.996285867s.
[2025-03-15T18:38:13.105+0000] {spark_submit.py:488} INFO - 25/03/15 18:37:49 WARN TaskSchedulerImpl: Initial job has not accepted any resources; check your cluster UI to ensure that workers are registered and have sufficient resources
[2025-03-15T18:38:33.370+0000] {spark_submit.py:488} INFO - 25/03/15 18:38:02 WARN TaskSchedulerImpl: Initial job has not accepted any resources; check your cluster UI to ensure that workers are registered and have sufficient resources
[2025-03-15T18:38:42.153+0000] {spark_submit.py:488} INFO - 25/03/15 18:38:08 INFO AsyncEventQueue: Process of event SparkListenerExecutorMetricsUpdate(driver,WrappedArray(),Map((-1,-1) -> org.apache.spark.executor.ExecutorMetrics@69650321)) by listener AppStatusListener took 20.160472788s.
[2025-03-15T18:38:57.842+0000] {spark_submit.py:488} INFO - 25/03/15 18:38:18 WARN TaskSchedulerImpl: Initial job has not accepted any resources; check your cluster UI to ensure that workers are registered and have sufficient resources
[2025-03-15T18:38:58.804+0000] {spark_submit.py:488} INFO - 25/03/15 18:38:44 INFO AsyncEventQueue: Process of event SparkListenerExecutorMetricsUpdate(driver,WrappedArray(),Map((-1,-1) -> org.apache.spark.executor.ExecutorMetrics@45a8675e)) by listener AppStatusListener took 8.67000457s.
[2025-03-15T18:38:59.433+0000] {spark_submit.py:488} INFO - 25/03/15 18:38:45 WARN TaskSchedulerImpl: Initial job has not accepted any resources; check your cluster UI to ensure that workers are registered and have sufficient resources
[2025-03-15T18:39:01.244+0000] {spark_submit.py:488} INFO - 25/03/15 18:38:48 WARN TaskSchedulerImpl: Initial job has not accepted any resources; check your cluster UI to ensure that workers are registered and have sufficient resources
[2025-03-15T18:39:01.416+0000] {spark_submit.py:488} INFO - 25/03/15 18:38:58 INFO AsyncEventQueue: Process of event SparkListenerExecutorMetricsUpdate(driver,WrappedArray(),Map((-1,-1) -> org.apache.spark.executor.ExecutorMetrics@548241af)) by listener AppStatusListener took 11.512887708s.
[2025-03-15T18:39:31.556+0000] {job.py:254} ERROR - Job heartbeat failed with error. Scheduler is in unhealthy state
[2025-03-15T18:39:31.991+0000] {local_task_job_runner.py:228} ERROR - Heartbeat time limit exceeded!
[2025-03-15T18:39:32.323+0000] {local_task_job_runner.py:245} INFO - ::endgroup::
[2025-03-15T18:39:35.113+0000] {process_utils.py:132} INFO - Sending 15 to group 279. PIDs of all processes in the group: [281, 320, 279]
[2025-03-15T18:39:35.539+0000] {process_utils.py:87} INFO - Sending the signal 15 to group 279
[2025-03-15T18:39:35.860+0000] {taskinstance.py:3094} ERROR - Received SIGTERM. Terminating subprocesses.
[2025-03-15T18:39:36.291+0000] {process_utils.py:80} INFO - Process psutil.Process(pid=320, status='terminated', started='18:33:24') (320) terminated with exit code None
[2025-03-15T18:39:36.864+0000] {taskinstance.py:3095} ERROR - Stacktrace: 
  File "/home/***/.local/bin/***", line 8, in <module>
    sys.exit(main())
  File "/home/***/.local/lib/python3.12/site-packages/***/__main__.py", line 62, in main
    args.func(args)
  File "/home/***/.local/lib/python3.12/site-packages/***/cli/cli_config.py", line 49, in command
    return func(*args, **kwargs)
  File "/home/***/.local/lib/python3.12/site-packages/***/utils/cli.py", line 116, in wrapper
    return f(*args, **kwargs)
  File "/home/***/.local/lib/python3.12/site-packages/***/providers/celery/cli/celery_command.py", line 64, in wrapper
    providers_configuration_loaded(func)(*args, **kwargs)
  File "/home/***/.local/lib/python3.12/site-packages/***/utils/providers_configuration_loader.py", line 55, in wrapped_function
    return func(*args, **kwargs)
  File "/home/***/.local/lib/python3.12/site-packages/***/providers/celery/cli/celery_command.py", line 237, in worker
    _run_command_with_daemon_option(
  File "/home/***/.local/lib/python3.12/site-packages/***/providers/celery/cli/celery_command.py", line 50, in _run_command_with_daemon_option
    run_command_with_daemon_option(*args, **kwargs)
  File "/home/***/.local/lib/python3.12/site-packages/***/cli/commands/daemon_utils.py", line 86, in run_command_with_daemon_option
    callback()
  File "/home/***/.local/lib/python3.12/site-packages/***/providers/celery/cli/celery_command.py", line 230, in run_celery_worker
    celery_app.worker_main(options)
  File "/home/***/.local/lib/python3.12/site-packages/celery/app/base.py", line 391, in worker_main
    self.start(argv=argv)
  File "/home/***/.local/lib/python3.12/site-packages/celery/app/base.py", line 371, in start
    celery.main(args=argv, standalone_mode=False)
  File "/home/***/.local/lib/python3.12/site-packages/click/core.py", line 1082, in main
    rv = self.invoke(ctx)
  File "/home/***/.local/lib/python3.12/site-packages/click/core.py", line 1697, in invoke
    return _process_result(sub_ctx.command.invoke(sub_ctx))
  File "/home/***/.local/lib/python3.12/site-packages/click/core.py", line 1443, in invoke
    return ctx.invoke(self.callback, **ctx.params)
  File "/home/***/.local/lib/python3.12/site-packages/click/core.py", line 788, in invoke
    return __callback(*args, **kwargs)
  File "/home/***/.local/lib/python3.12/site-packages/click/decorators.py", line 33, in new_func
    return f(get_current_context(), *args, **kwargs)
  File "/home/***/.local/lib/python3.12/site-packages/celery/bin/base.py", line 135, in caller
    return f(ctx, *args, **kwargs)
  File "/home/***/.local/lib/python3.12/site-packages/celery/bin/worker.py", line 356, in worker
    worker.start()
  File "/home/***/.local/lib/python3.12/site-packages/celery/worker/worker.py", line 202, in start
    self.blueprint.start(self)
  File "/home/***/.local/lib/python3.12/site-packages/celery/bootsteps.py", line 116, in start
    step.start(parent)
  File "/home/***/.local/lib/python3.12/site-packages/celery/bootsteps.py", line 365, in start
    return self.obj.start()
  File "/home/***/.local/lib/python3.12/site-packages/celery/concurrency/base.py", line 130, in start
    self.on_start()
  File "/home/***/.local/lib/python3.12/site-packages/celery/concurrency/prefork.py", line 109, in on_start
    P = self._pool = Pool(processes=self.limit,
  File "/home/***/.local/lib/python3.12/site-packages/celery/concurrency/asynpool.py", line 464, in __init__
    super().__init__(processes, *args, **kwargs)
  File "/home/***/.local/lib/python3.12/site-packages/billiard/pool.py", line 1046, in __init__
    self._create_worker_process(i)
  File "/home/***/.local/lib/python3.12/site-packages/celery/concurrency/asynpool.py", line 482, in _create_worker_process
    return super()._create_worker_process(i)
  File "/home/***/.local/lib/python3.12/site-packages/billiard/pool.py", line 1158, in _create_worker_process
    w.start()
  File "/home/***/.local/lib/python3.12/site-packages/billiard/process.py", line 120, in start
    self._popen = self._Popen(self)
  File "/home/***/.local/lib/python3.12/site-packages/billiard/context.py", line 331, in _Popen
    return Popen(process_obj)
  File "/home/***/.local/lib/python3.12/site-packages/billiard/popen_fork.py", line 22, in __init__
    self._launch(process_obj)
  File "/home/***/.local/lib/python3.12/site-packages/billiard/popen_fork.py", line 77, in _launch
    code = process_obj._bootstrap()
  File "/home/***/.local/lib/python3.12/site-packages/billiard/process.py", line 323, in _bootstrap
    self.run()
  File "/home/***/.local/lib/python3.12/site-packages/billiard/process.py", line 110, in run
    self._target(*self._args, **self._kwargs)
  File "/home/***/.local/lib/python3.12/site-packages/billiard/pool.py", line 292, in __call__
    sys.exit(self.workloop(pid=pid))
  File "/home/***/.local/lib/python3.12/site-packages/billiard/pool.py", line 362, in workloop
    result = (True, prepare_result(fun(*args, **kwargs)))
  File "/home/***/.local/lib/python3.12/site-packages/celery/app/trace.py", line 651, in fast_trace_task
    R, I, T, Rstr = tasks[task].__trace__(
  File "/home/***/.local/lib/python3.12/site-packages/celery/app/trace.py", line 453, in trace_task
    R = retval = fun(*args, **kwargs)
  File "/home/***/.local/lib/python3.12/site-packages/celery/app/trace.py", line 736, in __protected_call__
    return self.run(*args, **kwargs)
  File "/home/***/.local/lib/python3.12/site-packages/***/providers/celery/executors/celery_executor_utils.py", line 139, in execute_command
    _execute_in_fork(command_to_exec, celery_task_id)
  File "/home/***/.local/lib/python3.12/site-packages/***/providers/celery/executors/celery_executor_utils.py", line 171, in _execute_in_fork
    args.func(args)
  File "/home/***/.local/lib/python3.12/site-packages/***/cli/cli_config.py", line 49, in command
    return func(*args, **kwargs)
  File "/home/***/.local/lib/python3.12/site-packages/***/utils/cli.py", line 116, in wrapper
    return f(*args, **kwargs)
  File "/home/***/.local/lib/python3.12/site-packages/***/cli/commands/task_command.py", line 483, in task_run
    task_return_code = _run_task_by_selected_method(args, _dag, ti)
  File "/home/***/.local/lib/python3.12/site-packages/***/cli/commands/task_command.py", line 254, in _run_task_by_selected_method
    return _run_task_by_local_task_job(args, ti)
  File "/home/***/.local/lib/python3.12/site-packages/***/cli/commands/task_command.py", line 322, in _run_task_by_local_task_job
    ret = run_job(job=job_runner.job, execute_callable=job_runner._execute)
  File "/home/***/.local/lib/python3.12/site-packages/***/utils/session.py", line 97, in wrapper
    return func(*args, session=session, **kwargs)
  File "/home/***/.local/lib/python3.12/site-packages/***/jobs/job.py", line 421, in run_job
    return execute_job(job, execute_callable=execute_callable)
  File "/home/***/.local/lib/python3.12/site-packages/***/jobs/job.py", line 450, in execute_job
    ret = execute_callable()
  File "/home/***/.local/lib/python3.12/site-packages/***/jobs/local_task_job_runner.py", line 171, in _execute
    self.task_runner.start()
  File "/home/***/.local/lib/python3.12/site-packages/***/task/task_runner/standard_task_runner.py", line 55, in start
    self.process = self._start_by_fork()
  File "/home/***/.local/lib/python3.12/site-packages/***/task/task_runner/standard_task_runner.py", line 117, in _start_by_fork
    ret = args.func(args, dag=self.dag)
  File "/home/***/.local/lib/python3.12/site-packages/***/cli/cli_config.py", line 49, in command
    return func(*args, **kwargs)
  File "/home/***/.local/lib/python3.12/site-packages/***/utils/cli.py", line 116, in wrapper
    return f(*args, **kwargs)
  File "/home/***/.local/lib/python3.12/site-packages/***/cli/commands/task_command.py", line 483, in task_run
    task_return_code = _run_task_by_selected_method(args, _dag, ti)
  File "/home/***/.local/lib/python3.12/site-packages/***/cli/commands/task_command.py", line 256, in _run_task_by_selected_method
    return _run_raw_task(args, ti)
  File "/home/***/.local/lib/python3.12/site-packages/***/cli/commands/task_command.py", line 341, in _run_raw_task
    return ti._run_raw_task(
  File "/home/***/.local/lib/python3.12/site-packages/***/utils/session.py", line 97, in wrapper
    return func(*args, session=session, **kwargs)
  File "/home/***/.local/lib/python3.12/site-packages/***/models/taskinstance.py", line 3006, in _run_raw_task
    return _run_raw_task(
  File "/home/***/.local/lib/python3.12/site-packages/***/models/taskinstance.py", line 274, in _run_raw_task
    TaskInstance._execute_task_with_callbacks(
  File "/home/***/.local/lib/python3.12/site-packages/***/models/taskinstance.py", line 3161, in _execute_task_with_callbacks
    result = self._execute_task(context, task_orig)
  File "/home/***/.local/lib/python3.12/site-packages/***/models/taskinstance.py", line 3185, in _execute_task
    return _execute_task(self, context, task_orig)
  File "/home/***/.local/lib/python3.12/site-packages/***/models/taskinstance.py", line 768, in _execute_task
    result = _execute_callable(context=context, **execute_callable_kwargs)
  File "/home/***/.local/lib/python3.12/site-packages/***/models/taskinstance.py", line 734, in _execute_callable
    return ExecutionCallableRunner(
  File "/home/***/.local/lib/python3.12/site-packages/***/utils/operator_helpers.py", line 252, in run
    return self.func(*args, **kwargs)
  File "/home/***/.local/lib/python3.12/site-packages/***/models/baseoperator.py", line 424, in wrapper
    return func(self, *args, **kwargs)
  File "/home/***/.local/lib/python3.12/site-packages/***/providers/apache/spark/operators/spark_submit.py", line 157, in execute
    self._hook.submit(self._application)
  File "/home/***/.local/lib/python3.12/site-packages/***/providers/apache/spark/hooks/spark_submit.py", line 407, in submit
    self._process_spark_submit_log(iter(self._submit_sp.stdout))  # type: ignore
  File "/home/***/.local/lib/python3.12/site-packages/***/providers/apache/spark/hooks/spark_submit.py", line 456, in _process_spark_submit_log
    for line in itr:
  File "/home/***/.local/lib/python3.12/site-packages/***/models/taskinstance.py", line 3095, in signal_handler
    self.log.error("Stacktrace: \n%s", "".join(traceback.format_stack()))

[2025-03-15T18:39:38.553+0000] {spark_submit.py:623} INFO - Sending kill signal to spark-submit
[2025-03-15T18:39:46.046+0000] {taskinstance.py:341} INFO - ::group::Post task execution logs
[2025-03-15T18:39:46.078+0000] {standard_task_runner.py:124} ERROR - Failed to execute job 115 for task first_task ((psycopg2.OperationalError) could not translate host name "postgres" to address: Temporary failure in name resolution

(Background on this error at: https://sqlalche.me/e/14/e3q8); 279)
Traceback (most recent call last):
  File "/home/airflow/.local/lib/python3.12/site-packages/airflow/models/taskinstance.py", line 274, in _run_raw_task
    TaskInstance._execute_task_with_callbacks(
  File "/home/airflow/.local/lib/python3.12/site-packages/airflow/models/taskinstance.py", line 3161, in _execute_task_with_callbacks
    result = self._execute_task(context, task_orig)
             ^^^^^^^^^^^^^^^^^^^^^^^^^^^^^^^^^^^^^^
  File "/home/airflow/.local/lib/python3.12/site-packages/airflow/models/taskinstance.py", line 3185, in _execute_task
    return _execute_task(self, context, task_orig)
           ^^^^^^^^^^^^^^^^^^^^^^^^^^^^^^^^^^^^^^^
  File "/home/airflow/.local/lib/python3.12/site-packages/airflow/models/taskinstance.py", line 768, in _execute_task
    result = _execute_callable(context=context, **execute_callable_kwargs)
             ^^^^^^^^^^^^^^^^^^^^^^^^^^^^^^^^^^^^^^^^^^^^^^^^^^^^^^^^^^^^^
  File "/home/airflow/.local/lib/python3.12/site-packages/airflow/models/taskinstance.py", line 734, in _execute_callable
    return ExecutionCallableRunner(
           ^^^^^^^^^^^^^^^^^^^^^^^^
  File "/home/airflow/.local/lib/python3.12/site-packages/airflow/utils/operator_helpers.py", line 252, in run
    return self.func(*args, **kwargs)
           ^^^^^^^^^^^^^^^^^^^^^^^^^^
  File "/home/airflow/.local/lib/python3.12/site-packages/airflow/models/baseoperator.py", line 424, in wrapper
    return func(self, *args, **kwargs)
           ^^^^^^^^^^^^^^^^^^^^^^^^^^^
  File "/home/airflow/.local/lib/python3.12/site-packages/airflow/providers/apache/spark/operators/spark_submit.py", line 157, in execute
    self._hook.submit(self._application)
  File "/home/airflow/.local/lib/python3.12/site-packages/airflow/providers/apache/spark/hooks/spark_submit.py", line 407, in submit
    self._process_spark_submit_log(iter(self._submit_sp.stdout))  # type: ignore
    ^^^^^^^^^^^^^^^^^^^^^^^^^^^^^^^^^^^^^^^^^^^^^^^^^^^^^^^^^^^^
  File "/home/airflow/.local/lib/python3.12/site-packages/airflow/providers/apache/spark/hooks/spark_submit.py", line 456, in _process_spark_submit_log
    for line in itr:
                ^^^
  File "/home/airflow/.local/lib/python3.12/site-packages/airflow/models/taskinstance.py", line 3097, in signal_handler
    raise AirflowTaskTerminated("Task received SIGTERM signal")
airflow.exceptions.AirflowTaskTerminated: Task received SIGTERM signal

During handling of the above exception, another exception occurred:

Traceback (most recent call last):
  File "/home/airflow/.local/lib/python3.12/site-packages/sqlalchemy/engine/base.py", line 3371, in _wrap_pool_connect
    return fn()
           ^^^^
  File "/home/airflow/.local/lib/python3.12/site-packages/sqlalchemy/pool/base.py", line 327, in connect
    return _ConnectionFairy._checkout(self)
           ^^^^^^^^^^^^^^^^^^^^^^^^^^^^^^^^
  File "/home/airflow/.local/lib/python3.12/site-packages/sqlalchemy/pool/base.py", line 894, in _checkout
    fairy = _ConnectionRecord.checkout(pool)
            ^^^^^^^^^^^^^^^^^^^^^^^^^^^^^^^^
  File "/home/airflow/.local/lib/python3.12/site-packages/sqlalchemy/pool/base.py", line 493, in checkout
    rec = pool._do_get()
          ^^^^^^^^^^^^^^
  File "/home/airflow/.local/lib/python3.12/site-packages/sqlalchemy/pool/impl.py", line 256, in _do_get
    return self._create_connection()
           ^^^^^^^^^^^^^^^^^^^^^^^^^
  File "/home/airflow/.local/lib/python3.12/site-packages/sqlalchemy/pool/base.py", line 273, in _create_connection
    return _ConnectionRecord(self)
           ^^^^^^^^^^^^^^^^^^^^^^^
  File "/home/airflow/.local/lib/python3.12/site-packages/sqlalchemy/pool/base.py", line 388, in __init__
    self.__connect()
  File "/home/airflow/.local/lib/python3.12/site-packages/sqlalchemy/pool/base.py", line 690, in __connect
    with util.safe_reraise():
         ^^^^^^^^^^^^^^^^^^^
  File "/home/airflow/.local/lib/python3.12/site-packages/sqlalchemy/util/langhelpers.py", line 70, in __exit__
    compat.raise_(
  File "/home/airflow/.local/lib/python3.12/site-packages/sqlalchemy/util/compat.py", line 211, in raise_
    raise exception
  File "/home/airflow/.local/lib/python3.12/site-packages/sqlalchemy/pool/base.py", line 686, in __connect
    self.dbapi_connection = connection = pool._invoke_creator(self)
                                         ^^^^^^^^^^^^^^^^^^^^^^^^^^
  File "/home/airflow/.local/lib/python3.12/site-packages/sqlalchemy/engine/create.py", line 574, in connect
    return dialect.connect(*cargs, **cparams)
           ^^^^^^^^^^^^^^^^^^^^^^^^^^^^^^^^^^
  File "/home/airflow/.local/lib/python3.12/site-packages/sqlalchemy/engine/default.py", line 598, in connect
    return self.dbapi.connect(*cargs, **cparams)
           ^^^^^^^^^^^^^^^^^^^^^^^^^^^^^^^^^^^^^
  File "/home/airflow/.local/lib/python3.12/site-packages/psycopg2/__init__.py", line 122, in connect
    conn = _connect(dsn, connection_factory=connection_factory, **kwasync)
           ^^^^^^^^^^^^^^^^^^^^^^^^^^^^^^^^^^^^^^^^^^^^^^^^^^^^^^^^^^^^^^^
psycopg2.OperationalError: could not translate host name "postgres" to address: Temporary failure in name resolution


The above exception was the direct cause of the following exception:

Traceback (most recent call last):
  File "/home/airflow/.local/lib/python3.12/site-packages/airflow/task/task_runner/standard_task_runner.py", line 117, in _start_by_fork
    ret = args.func(args, dag=self.dag)
          ^^^^^^^^^^^^^^^^^^^^^^^^^^^^^
  File "/home/airflow/.local/lib/python3.12/site-packages/airflow/cli/cli_config.py", line 49, in command
    return func(*args, **kwargs)
           ^^^^^^^^^^^^^^^^^^^^^
  File "/home/airflow/.local/lib/python3.12/site-packages/airflow/utils/cli.py", line 116, in wrapper
    return f(*args, **kwargs)
           ^^^^^^^^^^^^^^^^^^
  File "/home/airflow/.local/lib/python3.12/site-packages/airflow/cli/commands/task_command.py", line 483, in task_run
    task_return_code = _run_task_by_selected_method(args, _dag, ti)
                       ^^^^^^^^^^^^^^^^^^^^^^^^^^^^^^^^^^^^^^^^^^^^
  File "/home/airflow/.local/lib/python3.12/site-packages/airflow/cli/commands/task_command.py", line 256, in _run_task_by_selected_method
    return _run_raw_task(args, ti)
           ^^^^^^^^^^^^^^^^^^^^^^^
  File "/home/airflow/.local/lib/python3.12/site-packages/airflow/cli/commands/task_command.py", line 341, in _run_raw_task
    return ti._run_raw_task(
           ^^^^^^^^^^^^^^^^^
  File "/home/airflow/.local/lib/python3.12/site-packages/airflow/utils/session.py", line 97, in wrapper
    return func(*args, session=session, **kwargs)
           ^^^^^^^^^^^^^^^^^^^^^^^^^^^^^^^^^^^^^^
  File "/home/airflow/.local/lib/python3.12/site-packages/airflow/models/taskinstance.py", line 3006, in _run_raw_task
    return _run_raw_task(
           ^^^^^^^^^^^^^^
  File "/home/airflow/.local/lib/python3.12/site-packages/airflow/models/taskinstance.py", line 319, in _run_raw_task
    ti.refresh_from_db(lock_for_update=True, session=session)
  File "/home/airflow/.local/lib/python3.12/site-packages/airflow/utils/session.py", line 94, in wrapper
    return func(*args, **kwargs)
           ^^^^^^^^^^^^^^^^^^^^^
  File "/home/airflow/.local/lib/python3.12/site-packages/airflow/models/taskinstance.py", line 2360, in refresh_from_db
    _refresh_from_db(task_instance=self, session=session, lock_for_update=lock_for_update)
  File "/home/airflow/.local/lib/python3.12/site-packages/airflow/models/taskinstance.py", line 873, in _refresh_from_db
    ti = TaskInstance.get_task_instance(
         ^^^^^^^^^^^^^^^^^^^^^^^^^^^^^^^
  File "/home/airflow/.local/lib/python3.12/site-packages/airflow/api_internal/internal_api_call.py", line 166, in wrapper
    return func(*args, **kwargs)
           ^^^^^^^^^^^^^^^^^^^^^
  File "/home/airflow/.local/lib/python3.12/site-packages/airflow/utils/session.py", line 94, in wrapper
    return func(*args, **kwargs)
           ^^^^^^^^^^^^^^^^^^^^^
  File "/home/airflow/.local/lib/python3.12/site-packages/airflow/models/taskinstance.py", line 2342, in get_task_instance
    for attempt in run_with_db_retries(logger=cls.logger()):
                   ^^^^^^^^^^^^^^^^^^^^^^^^^^^^^^^^^^^^^^^^
  File "/home/airflow/.local/lib/python3.12/site-packages/tenacity/__init__.py", line 443, in __iter__
    do = self.iter(retry_state=retry_state)
         ^^^^^^^^^^^^^^^^^^^^^^^^^^^^^^^^^^
  File "/home/airflow/.local/lib/python3.12/site-packages/tenacity/__init__.py", line 376, in iter
    result = action(retry_state)
             ^^^^^^^^^^^^^^^^^^^
  File "/home/airflow/.local/lib/python3.12/site-packages/tenacity/__init__.py", line 418, in exc_check
    raise retry_exc.reraise()
          ^^^^^^^^^^^^^^^^^^^
  File "/home/airflow/.local/lib/python3.12/site-packages/tenacity/__init__.py", line 185, in reraise
    raise self.last_attempt.result()
          ^^^^^^^^^^^^^^^^^^^^^^^^^^
  File "/usr/local/lib/python3.12/concurrent/futures/_base.py", line 449, in result
    return self.__get_result()
           ^^^^^^^^^^^^^^^^^^^
  File "/usr/local/lib/python3.12/concurrent/futures/_base.py", line 401, in __get_result
    raise self._exception
  File "/home/airflow/.local/lib/python3.12/site-packages/airflow/models/taskinstance.py", line 2344, in get_task_instance
    return query.with_for_update().one_or_none()
           ^^^^^^^^^^^^^^^^^^^^^^^^^^^^^^^^^^^^^
  File "/home/airflow/.local/lib/python3.12/site-packages/sqlalchemy/orm/query.py", line 2850, in one_or_none
    return self._iter().one_or_none()
           ^^^^^^^^^^^^
  File "/home/airflow/.local/lib/python3.12/site-packages/sqlalchemy/orm/query.py", line 2916, in _iter
    result = self.session.execute(
             ^^^^^^^^^^^^^^^^^^^^^
  File "/home/airflow/.local/lib/python3.12/site-packages/sqlalchemy/orm/session.py", line 1716, in execute
    conn = self._connection_for_bind(bind)
           ^^^^^^^^^^^^^^^^^^^^^^^^^^^^^^^
  File "/home/airflow/.local/lib/python3.12/site-packages/sqlalchemy/orm/session.py", line 1555, in _connection_for_bind
    return self._transaction._connection_for_bind(
           ^^^^^^^^^^^^^^^^^^^^^^^^^^^^^^^^^^^^^^^
  File "/home/airflow/.local/lib/python3.12/site-packages/sqlalchemy/orm/session.py", line 750, in _connection_for_bind
    conn = bind.connect()
           ^^^^^^^^^^^^^^
  File "/home/airflow/.local/lib/python3.12/site-packages/sqlalchemy/future/engine.py", line 412, in connect
    return super(Engine, self).connect()
           ^^^^^^^^^^^^^^^^^^^^^^^^^^^^^
  File "/home/airflow/.local/lib/python3.12/site-packages/sqlalchemy/engine/base.py", line 3325, in connect
    return self._connection_cls(self, close_with_result=close_with_result)
           ^^^^^^^^^^^^^^^^^^^^^^^^^^^^^^^^^^^^^^^^^^^^^^^^^^^^^^^^^^^^^^^
  File "/home/airflow/.local/lib/python3.12/site-packages/sqlalchemy/engine/base.py", line 96, in __init__
    else engine.raw_connection()
         ^^^^^^^^^^^^^^^^^^^^^^^
  File "/home/airflow/.local/lib/python3.12/site-packages/sqlalchemy/engine/base.py", line 3404, in raw_connection
    return self._wrap_pool_connect(self.pool.connect, _connection)
           ^^^^^^^^^^^^^^^^^^^^^^^^^^^^^^^^^^^^^^^^^^^^^^^^^^^^^^^
  File "/home/airflow/.local/lib/python3.12/site-packages/sqlalchemy/engine/base.py", line 3374, in _wrap_pool_connect
    Connection._handle_dbapi_exception_noconnection(
  File "/home/airflow/.local/lib/python3.12/site-packages/sqlalchemy/engine/base.py", line 2208, in _handle_dbapi_exception_noconnection
    util.raise_(
  File "/home/airflow/.local/lib/python3.12/site-packages/sqlalchemy/util/compat.py", line 211, in raise_
    raise exception
  File "/home/airflow/.local/lib/python3.12/site-packages/sqlalchemy/engine/base.py", line 3371, in _wrap_pool_connect
    return fn()
           ^^^^
  File "/home/airflow/.local/lib/python3.12/site-packages/sqlalchemy/pool/base.py", line 327, in connect
    return _ConnectionFairy._checkout(self)
           ^^^^^^^^^^^^^^^^^^^^^^^^^^^^^^^^
  File "/home/airflow/.local/lib/python3.12/site-packages/sqlalchemy/pool/base.py", line 894, in _checkout
    fairy = _ConnectionRecord.checkout(pool)
            ^^^^^^^^^^^^^^^^^^^^^^^^^^^^^^^^
  File "/home/airflow/.local/lib/python3.12/site-packages/sqlalchemy/pool/base.py", line 493, in checkout
    rec = pool._do_get()
          ^^^^^^^^^^^^^^
  File "/home/airflow/.local/lib/python3.12/site-packages/sqlalchemy/pool/impl.py", line 256, in _do_get
    return self._create_connection()
           ^^^^^^^^^^^^^^^^^^^^^^^^^
  File "/home/airflow/.local/lib/python3.12/site-packages/sqlalchemy/pool/base.py", line 273, in _create_connection
    return _ConnectionRecord(self)
           ^^^^^^^^^^^^^^^^^^^^^^^
  File "/home/airflow/.local/lib/python3.12/site-packages/sqlalchemy/pool/base.py", line 388, in __init__
    self.__connect()
  File "/home/airflow/.local/lib/python3.12/site-packages/sqlalchemy/pool/base.py", line 690, in __connect
    with util.safe_reraise():
         ^^^^^^^^^^^^^^^^^^^
  File "/home/airflow/.local/lib/python3.12/site-packages/sqlalchemy/util/langhelpers.py", line 70, in __exit__
    compat.raise_(
  File "/home/airflow/.local/lib/python3.12/site-packages/sqlalchemy/util/compat.py", line 211, in raise_
    raise exception
  File "/home/airflow/.local/lib/python3.12/site-packages/sqlalchemy/pool/base.py", line 686, in __connect
    self.dbapi_connection = connection = pool._invoke_creator(self)
                                         ^^^^^^^^^^^^^^^^^^^^^^^^^^
  File "/home/airflow/.local/lib/python3.12/site-packages/sqlalchemy/engine/create.py", line 574, in connect
    return dialect.connect(*cargs, **cparams)
           ^^^^^^^^^^^^^^^^^^^^^^^^^^^^^^^^^^
  File "/home/airflow/.local/lib/python3.12/site-packages/sqlalchemy/engine/default.py", line 598, in connect
    return self.dbapi.connect(*cargs, **cparams)
           ^^^^^^^^^^^^^^^^^^^^^^^^^^^^^^^^^^^^^
  File "/home/airflow/.local/lib/python3.12/site-packages/psycopg2/__init__.py", line 122, in connect
    conn = _connect(dsn, connection_factory=connection_factory, **kwasync)
           ^^^^^^^^^^^^^^^^^^^^^^^^^^^^^^^^^^^^^^^^^^^^^^^^^^^^^^^^^^^^^^^
sqlalchemy.exc.OperationalError: (psycopg2.OperationalError) could not translate host name "postgres" to address: Temporary failure in name resolution

(Background on this error at: https://sqlalche.me/e/14/e3q8)
[2025-03-15T18:39:46.447+0000] {process_utils.py:80} INFO - Process psutil.Process(pid=281, status='terminated', started='18:33:19') (281) terminated with exit code None
[2025-03-15T18:39:46.455+0000] {process_utils.py:80} INFO - Process psutil.Process(pid=279, status='terminated', exitcode=1, started='18:33:19') (279) terminated with exit code 1
