[2025-03-20T05:07:35.145+0000] {processor.py:186} INFO - Started process (PID=61) to work on /opt/airflow/dags/mainDag.py
[2025-03-20T05:07:35.149+0000] {processor.py:914} INFO - Processing file /opt/airflow/dags/mainDag.py for tasks to queue
[2025-03-20T05:07:35.152+0000] {logging_mixin.py:190} INFO - [2025-03-20T05:07:35.152+0000] {dagbag.py:588} INFO - Filling up the DagBag from /opt/airflow/dags/mainDag.py
[2025-03-20T05:07:41.454+0000] {processor.py:925} INFO - DAG(s) 'solar_energy_crops_pipeline' retrieved from /opt/airflow/dags/mainDag.py
[2025-03-20T05:07:42.002+0000] {logging_mixin.py:190} INFO - [2025-03-20T05:07:42.001+0000] {dag.py:3239} INFO - Sync 1 DAGs
[2025-03-20T05:07:42.086+0000] {logging_mixin.py:190} INFO - [2025-03-20T05:07:42.086+0000] {dag.py:4180} INFO - Setting next_dagrun for solar_energy_crops_pipeline to 2025-03-20 00:00:00+00:00, run_after=2025-03-21 00:00:00+00:00
[2025-03-20T05:07:42.141+0000] {processor.py:208} INFO - Processing /opt/airflow/dags/mainDag.py took 7.007 seconds
[2025-03-20T05:08:17.872+0000] {processor.py:186} INFO - Started process (PID=70) to work on /opt/airflow/dags/mainDag.py
[2025-03-20T05:08:17.885+0000] {processor.py:914} INFO - Processing file /opt/airflow/dags/mainDag.py for tasks to queue
[2025-03-20T05:08:17.923+0000] {logging_mixin.py:190} INFO - [2025-03-20T05:08:17.908+0000] {dagbag.py:588} INFO - Filling up the DagBag from /opt/airflow/dags/mainDag.py
[2025-03-20T05:08:51.239+0000] {logging_mixin.py:190} INFO - [2025-03-20T05:08:51.169+0000] {timeout.py:68} ERROR - Process timed out, PID: 70
[2025-03-20T05:08:51.373+0000] {logging_mixin.py:190} INFO - [2025-03-20T05:08:51.250+0000] {dagbag.py:387} ERROR - Failed to import: /opt/airflow/dags/mainDag.py
Traceback (most recent call last):
  File "/home/airflow/.local/lib/python3.12/site-packages/airflow/models/dagbag.py", line 383, in parse
    loader.exec_module(new_module)
  File "<frozen importlib._bootstrap_external>", line 999, in exec_module
  File "<frozen importlib._bootstrap>", line 488, in _call_with_frames_removed
  File "/opt/airflow/dags/mainDag.py", line 5, in <module>
    from extract import extract_data
  File "/opt/airflow/dags/extract.py", line 2, in <module>
    import pandas as pd
  File "/home/airflow/.local/lib/python3.12/site-packages/pandas/__init__.py", line 11, in <module>
    __import__(_dependency)
  File "/home/airflow/.local/lib/python3.12/site-packages/numpy/__init__.py", line 130, in <module>
    from numpy.__config__ import show as show_config
  File "/home/airflow/.local/lib/python3.12/site-packages/numpy/__config__.py", line 4, in <module>
    from numpy.core._multiarray_umath import (
  File "/home/airflow/.local/lib/python3.12/site-packages/numpy/core/__init__.py", line 24, in <module>
    from . import multiarray
  File "/home/airflow/.local/lib/python3.12/site-packages/numpy/core/multiarray.py", line 10, in <module>
    from . import overrides
  File "/home/airflow/.local/lib/python3.12/site-packages/numpy/core/overrides.py", line 8, in <module>
    from numpy.core._multiarray_umath import (
  File "<frozen importlib._bootstrap>", line 463, in _lock_unlock_module
  File "/home/airflow/.local/lib/python3.12/site-packages/airflow/utils/timeout.py", line 69, in handle_timeout
    raise AirflowTaskTimeout(self.error_message)
airflow.exceptions.AirflowTaskTimeout: DagBag import timeout for /opt/airflow/dags/mainDag.py after 30.0s.
Please take a look at these docs to improve your DAG import time:
* https://airflow.apache.org/docs/apache-airflow/2.10.5/best-practices.html#top-level-python-code
* https://airflow.apache.org/docs/apache-airflow/2.10.5/best-practices.html#reducing-dag-complexity, PID: 70
[2025-03-20T05:08:51.434+0000] {processor.py:927} WARNING - No viable dags retrieved from /opt/airflow/dags/mainDag.py
[2025-03-20T05:09:07.300+0000] {processor.py:211} ERROR - Got an exception! Propagating...
Traceback (most recent call last):
  File "/home/airflow/.local/lib/python3.12/site-packages/sqlalchemy/engine/base.py", line 3371, in _wrap_pool_connect
    return fn()
           ^^^^
  File "/home/airflow/.local/lib/python3.12/site-packages/sqlalchemy/pool/base.py", line 327, in connect
    return _ConnectionFairy._checkout(self)
           ^^^^^^^^^^^^^^^^^^^^^^^^^^^^^^^^
  File "/home/airflow/.local/lib/python3.12/site-packages/sqlalchemy/pool/base.py", line 894, in _checkout
    fairy = _ConnectionRecord.checkout(pool)
            ^^^^^^^^^^^^^^^^^^^^^^^^^^^^^^^^
  File "/home/airflow/.local/lib/python3.12/site-packages/sqlalchemy/pool/base.py", line 493, in checkout
    rec = pool._do_get()
          ^^^^^^^^^^^^^^
  File "/home/airflow/.local/lib/python3.12/site-packages/sqlalchemy/pool/impl.py", line 145, in _do_get
    with util.safe_reraise():
         ^^^^^^^^^^^^^^^^^^^
  File "/home/airflow/.local/lib/python3.12/site-packages/sqlalchemy/util/langhelpers.py", line 70, in __exit__
    compat.raise_(
  File "/home/airflow/.local/lib/python3.12/site-packages/sqlalchemy/util/compat.py", line 211, in raise_
    raise exception
  File "/home/airflow/.local/lib/python3.12/site-packages/sqlalchemy/pool/impl.py", line 143, in _do_get
    return self._create_connection()
           ^^^^^^^^^^^^^^^^^^^^^^^^^
  File "/home/airflow/.local/lib/python3.12/site-packages/sqlalchemy/pool/base.py", line 273, in _create_connection
    return _ConnectionRecord(self)
           ^^^^^^^^^^^^^^^^^^^^^^^
  File "/home/airflow/.local/lib/python3.12/site-packages/sqlalchemy/pool/base.py", line 388, in __init__
    self.__connect()
  File "/home/airflow/.local/lib/python3.12/site-packages/sqlalchemy/pool/base.py", line 690, in __connect
    with util.safe_reraise():
         ^^^^^^^^^^^^^^^^^^^
  File "/home/airflow/.local/lib/python3.12/site-packages/sqlalchemy/util/langhelpers.py", line 70, in __exit__
    compat.raise_(
  File "/home/airflow/.local/lib/python3.12/site-packages/sqlalchemy/util/compat.py", line 211, in raise_
    raise exception
  File "/home/airflow/.local/lib/python3.12/site-packages/sqlalchemy/pool/base.py", line 686, in __connect
    self.dbapi_connection = connection = pool._invoke_creator(self)
                                         ^^^^^^^^^^^^^^^^^^^^^^^^^^
  File "/home/airflow/.local/lib/python3.12/site-packages/sqlalchemy/engine/create.py", line 574, in connect
    return dialect.connect(*cargs, **cparams)
           ^^^^^^^^^^^^^^^^^^^^^^^^^^^^^^^^^^
  File "/home/airflow/.local/lib/python3.12/site-packages/sqlalchemy/engine/default.py", line 598, in connect
    return self.dbapi.connect(*cargs, **cparams)
           ^^^^^^^^^^^^^^^^^^^^^^^^^^^^^^^^^^^^^
  File "/home/airflow/.local/lib/python3.12/site-packages/psycopg2/__init__.py", line 122, in connect
    conn = _connect(dsn, connection_factory=connection_factory, **kwasync)
           ^^^^^^^^^^^^^^^^^^^^^^^^^^^^^^^^^^^^^^^^^^^^^^^^^^^^^^^^^^^^^^^
psycopg2.OperationalError: could not translate host name "postgres" to address: Temporary failure in name resolution


The above exception was the direct cause of the following exception:

Traceback (most recent call last):
  File "/home/airflow/.local/lib/python3.12/site-packages/airflow/dag_processing/processor.py", line 207, in _run_file_processor
    _handle_dag_file_processing()
  File "/home/airflow/.local/lib/python3.12/site-packages/airflow/dag_processing/processor.py", line 188, in _handle_dag_file_processing
    result: tuple[int, int, int] = dag_file_processor.process_file(
                                   ^^^^^^^^^^^^^^^^^^^^^^^^^^^^^^^^
  File "/home/airflow/.local/lib/python3.12/site-packages/airflow/utils/session.py", line 97, in wrapper
    return func(*args, session=session, **kwargs)
           ^^^^^^^^^^^^^^^^^^^^^^^^^^^^^^^^^^^^^^
  File "/home/airflow/.local/lib/python3.12/site-packages/airflow/dag_processing/processor.py", line 928, in process_file
    DagFileProcessor.update_import_errors(
  File "/home/airflow/.local/lib/python3.12/site-packages/airflow/api_internal/internal_api_call.py", line 166, in wrapper
    return func(*args, **kwargs)
           ^^^^^^^^^^^^^^^^^^^^^
  File "/home/airflow/.local/lib/python3.12/site-packages/airflow/utils/session.py", line 97, in wrapper
    return func(*args, session=session, **kwargs)
           ^^^^^^^^^^^^^^^^^^^^^^^^^^^^^^^^^^^^^^
  File "/home/airflow/.local/lib/python3.12/site-packages/airflow/dag_processing/processor.py", line 648, in update_import_errors
    existing_import_error_files = [x.filename for x in session.query(ParseImportError.filename).all()]
                                                       ^^^^^^^^^^^^^^^^^^^^^^^^^^^^^^^^^^^^^^^^^^^^^^
  File "/home/airflow/.local/lib/python3.12/site-packages/sqlalchemy/orm/query.py", line 2773, in all
    return self._iter().all()
           ^^^^^^^^^^^^
  File "/home/airflow/.local/lib/python3.12/site-packages/sqlalchemy/orm/query.py", line 2916, in _iter
    result = self.session.execute(
             ^^^^^^^^^^^^^^^^^^^^^
  File "/home/airflow/.local/lib/python3.12/site-packages/sqlalchemy/orm/session.py", line 1716, in execute
    conn = self._connection_for_bind(bind)
           ^^^^^^^^^^^^^^^^^^^^^^^^^^^^^^^
  File "/home/airflow/.local/lib/python3.12/site-packages/sqlalchemy/orm/session.py", line 1555, in _connection_for_bind
    return self._transaction._connection_for_bind(
           ^^^^^^^^^^^^^^^^^^^^^^^^^^^^^^^^^^^^^^^
  File "/home/airflow/.local/lib/python3.12/site-packages/sqlalchemy/orm/session.py", line 750, in _connection_for_bind
    conn = bind.connect()
           ^^^^^^^^^^^^^^
  File "/home/airflow/.local/lib/python3.12/site-packages/sqlalchemy/future/engine.py", line 412, in connect
    return super(Engine, self).connect()
           ^^^^^^^^^^^^^^^^^^^^^^^^^^^^^
  File "/home/airflow/.local/lib/python3.12/site-packages/sqlalchemy/engine/base.py", line 3325, in connect
    return self._connection_cls(self, close_with_result=close_with_result)
           ^^^^^^^^^^^^^^^^^^^^^^^^^^^^^^^^^^^^^^^^^^^^^^^^^^^^^^^^^^^^^^^
  File "/home/airflow/.local/lib/python3.12/site-packages/sqlalchemy/engine/base.py", line 96, in __init__
    else engine.raw_connection()
         ^^^^^^^^^^^^^^^^^^^^^^^
  File "/home/airflow/.local/lib/python3.12/site-packages/sqlalchemy/engine/base.py", line 3404, in raw_connection
    return self._wrap_pool_connect(self.pool.connect, _connection)
           ^^^^^^^^^^^^^^^^^^^^^^^^^^^^^^^^^^^^^^^^^^^^^^^^^^^^^^^
  File "/home/airflow/.local/lib/python3.12/site-packages/sqlalchemy/engine/base.py", line 3374, in _wrap_pool_connect
    Connection._handle_dbapi_exception_noconnection(
  File "/home/airflow/.local/lib/python3.12/site-packages/sqlalchemy/engine/base.py", line 2208, in _handle_dbapi_exception_noconnection
    util.raise_(
  File "/home/airflow/.local/lib/python3.12/site-packages/sqlalchemy/util/compat.py", line 211, in raise_
    raise exception
  File "/home/airflow/.local/lib/python3.12/site-packages/sqlalchemy/engine/base.py", line 3371, in _wrap_pool_connect
    return fn()
           ^^^^
  File "/home/airflow/.local/lib/python3.12/site-packages/sqlalchemy/pool/base.py", line 327, in connect
    return _ConnectionFairy._checkout(self)
           ^^^^^^^^^^^^^^^^^^^^^^^^^^^^^^^^
  File "/home/airflow/.local/lib/python3.12/site-packages/sqlalchemy/pool/base.py", line 894, in _checkout
    fairy = _ConnectionRecord.checkout(pool)
            ^^^^^^^^^^^^^^^^^^^^^^^^^^^^^^^^
  File "/home/airflow/.local/lib/python3.12/site-packages/sqlalchemy/pool/base.py", line 493, in checkout
    rec = pool._do_get()
          ^^^^^^^^^^^^^^
  File "/home/airflow/.local/lib/python3.12/site-packages/sqlalchemy/pool/impl.py", line 145, in _do_get
    with util.safe_reraise():
         ^^^^^^^^^^^^^^^^^^^
  File "/home/airflow/.local/lib/python3.12/site-packages/sqlalchemy/util/langhelpers.py", line 70, in __exit__
    compat.raise_(
  File "/home/airflow/.local/lib/python3.12/site-packages/sqlalchemy/util/compat.py", line 211, in raise_
    raise exception
  File "/home/airflow/.local/lib/python3.12/site-packages/sqlalchemy/pool/impl.py", line 143, in _do_get
    return self._create_connection()
           ^^^^^^^^^^^^^^^^^^^^^^^^^
  File "/home/airflow/.local/lib/python3.12/site-packages/sqlalchemy/pool/base.py", line 273, in _create_connection
    return _ConnectionRecord(self)
           ^^^^^^^^^^^^^^^^^^^^^^^
  File "/home/airflow/.local/lib/python3.12/site-packages/sqlalchemy/pool/base.py", line 388, in __init__
    self.__connect()
  File "/home/airflow/.local/lib/python3.12/site-packages/sqlalchemy/pool/base.py", line 690, in __connect
    with util.safe_reraise():
         ^^^^^^^^^^^^^^^^^^^
  File "/home/airflow/.local/lib/python3.12/site-packages/sqlalchemy/util/langhelpers.py", line 70, in __exit__
    compat.raise_(
  File "/home/airflow/.local/lib/python3.12/site-packages/sqlalchemy/util/compat.py", line 211, in raise_
    raise exception
  File "/home/airflow/.local/lib/python3.12/site-packages/sqlalchemy/pool/base.py", line 686, in __connect
    self.dbapi_connection = connection = pool._invoke_creator(self)
                                         ^^^^^^^^^^^^^^^^^^^^^^^^^^
  File "/home/airflow/.local/lib/python3.12/site-packages/sqlalchemy/engine/create.py", line 574, in connect
    return dialect.connect(*cargs, **cparams)
           ^^^^^^^^^^^^^^^^^^^^^^^^^^^^^^^^^^
  File "/home/airflow/.local/lib/python3.12/site-packages/sqlalchemy/engine/default.py", line 598, in connect
    return self.dbapi.connect(*cargs, **cparams)
           ^^^^^^^^^^^^^^^^^^^^^^^^^^^^^^^^^^^^^
  File "/home/airflow/.local/lib/python3.12/site-packages/psycopg2/__init__.py", line 122, in connect
    conn = _connect(dsn, connection_factory=connection_factory, **kwasync)
           ^^^^^^^^^^^^^^^^^^^^^^^^^^^^^^^^^^^^^^^^^^^^^^^^^^^^^^^^^^^^^^^
sqlalchemy.exc.OperationalError: (psycopg2.OperationalError) could not translate host name "postgres" to address: Temporary failure in name resolution

(Background on this error at: https://sqlalche.me/e/14/e3q8)
[2025-03-20T05:09:43.011+0000] {processor.py:186} INFO - Started process (PID=78) to work on /opt/airflow/dags/mainDag.py
[2025-03-20T05:09:43.032+0000] {processor.py:914} INFO - Processing file /opt/airflow/dags/mainDag.py for tasks to queue
[2025-03-20T05:09:43.070+0000] {logging_mixin.py:190} INFO - [2025-03-20T05:09:43.058+0000] {dagbag.py:588} INFO - Filling up the DagBag from /opt/airflow/dags/mainDag.py
